Workbook

Sheet Sommario
B1: Sommario
C2: Allenatore | D2: =IF(ISBLANK(Impostazioni!$D$9),"Inserisci dalle impostazioni",Impostazioni!$D$9) -> Inserisci dalle impostazioni
C3: Società | D3: =IF(ISBLANK(Impostazioni!$D$11),"Inserisci dalle impostazioni",Impostazioni!$D$11) -> Inserisci dalle impostazioni
C4: Squadra | D4: =IF(ISBLANK(Impostazioni!$D$15),"Inserisci dalle impostazioni",Impostazioni!$D$15) -> Inserisci dalle impostazioni
F6: Anno | G6: =Impostazioni!$D$5 -> 2025 | H6: =Impostazioni!$F$5 -> 2026 | I6: ←Inserisci la stagione nelle impostazioni
B8: =Impostazioni!$B$19&" - "&Impostazioni!$D$19&" | "&Impostazioni!$B$20&" - "&Impostazioni!$D$20&" | "&Impostazioni!$B$21&" - "&Impostazioni!$D$21&" | "&Impostazioni!$B$22&" - "&Impostazioni!$D$22&" | "&Impostazioni!$B$23&" - "&Impostazioni!$D$23 -> P - Presente | A - Assente | R - Ritardo | E - Impegno Pallavolistico | I - Infortunio
B10: Atleta | D10: Totali | O10: Allenamenti Totali: | Q10: =SUM(Agosto!AV10,Settembre!AV10,Ottobre!AV10,Novembre!AV10,Dicembre!AV10,Gennaio!AV10,Febbraio!AV10,Marzo!AV10,Aprile!AV10,Maggio!AV10,Giugno!AV10,Luglio!AV10) -> 0
B11: ID | C11: Nome | D11: =Impostazioni!$B$19 -> P | E11: =Impostazioni!$B$20 -> A | F11: =Impostazioni!$B$21 -> R | G11: =Impostazioni!$B$22 -> E | H11: =Impostazioni!$B$23 -> I | I11: =Impostazioni!$B$19 & "%" -> P% | J11: =Impostazioni!$B$20 & "%" -> A% | K11: =Impostazioni!$B$21 & "%" -> R% | L11: =Impostazioni!$B$22 & "%" -> E% | M11: =Impostazioni!$B$23 & "%" -> I%
B12: 1 | D12: {=IF(OR(ISBLANK($B12),ISBLANK($C12)),0,SUM(INDEX(Agosto!AI$12:AI$44,MATCH($B12,Agosto!$B$12:$B$44,0)),INDEX(Settembre!AI$12:AI$44,MATCH($B12,Settembre!$B$12:$B$44,0)),INDEX(Ottobre!AI$12:AI$44,MATCH($B12,Ottobre!$B$12:$B$44,0)),INDEX(Novembre!AI$12:AI$44,MATCH($B12,Novembre!$B$12:$B$44,0)),INDEX(Dicembre!AI$12:AI$44,MATCH($B12,Dicembre!$B$12:$B$44,0)),INDEX(Gennaio!AI$12:AI$44,MATCH($B12,Gennaio!$B$12:$B$44,0)),INDEX(Febbraio!AI$12:AI$44,MATCH($B12,Febbraio!$B$12:$B$44,0)),INDEX(Marzo!AI$12:AI$44,MATCH($B12,Marzo!$B$12:$B$44,0)),INDEX(Aprile!AI$12:AI$44,MATCH($B12,Aprile!$B$12:$B$44,0)),INDEX(Maggio!AI$12:AI$44,MATCH($B12,Maggio!$B$12:$B$44,0)),INDEX(Giugno!AI$12:AI$44,MATCH($B12,Giugno!$B$12:$B$44,0)),INDEX(Luglio!AI$12:AI$44,MATCH($B12,Luglio!$B$12:$B$44,0))))} -> 0 | E12: {=IF(OR(ISBLANK($B12),ISBLANK($C12)),0,SUM(INDEX(Agosto!AJ$12:AJ$44,MATCH($B12,Agosto!$B$12:$B$44,0)),INDEX(Settembre!AJ$12:AJ$44,MATCH($B12,Settembre!$B$12:$B$44,0)),INDEX(Ottobre!AJ$12:AJ$44,MATCH($B12,Ottobre!$B$12:$B$44,0)),INDEX(Novembre!AJ$12:AJ$44,MATCH($B12,Novembre!$B$12:$B$44,0)),INDEX(Dicembre!AJ$12:AJ$44,MATCH($B12,Dicembre!$B$12:$B$44,0)),INDEX(Gennaio!AJ$12:AJ$44,MATCH($B12,Gennaio!$B$12:$B$44,0)),INDEX(Febbraio!AJ$12:AJ$44,MATCH($B12,Febbraio!$B$12:$B$44,0)),INDEX(Marzo!AJ$12:AJ$44,MATCH($B12,Marzo!$B$12:$B$44,0)),INDEX(Aprile!AJ$12:AJ$44,MATCH($B12,Aprile!$B$12:$B$44,0)),INDEX(Maggio!AJ$12:AJ$44,MATCH($B12,Maggio!$B$12:$B$44,0)),INDEX(Giugno!AJ$12:AJ$44,MATCH($B12,Giugno!$B$12:$B$44,0)),INDEX(Luglio!AJ$12:AJ$44,MATCH($B12,Luglio!$B$12:$B$44,0))))} -> 0 | F12: {=IF(OR(ISBLANK($B12),ISBLANK($C12)),0,SUM(INDEX(Agosto!AK$12:AK$44,MATCH($B12,Agosto!$B$12:$B$44,0)),INDEX(Settembre!AK$12:AK$44,MATCH($B12,Settembre!$B$12:$B$44,0)),INDEX(Ottobre!AK$12:AK$44,MATCH($B12,Ottobre!$B$12:$B$44,0)),INDEX(Novembre!AK$12:AK$44,MATCH($B12,Novembre!$B$12:$B$44,0)),INDEX(Dicembre!AK$12:AK$44,MATCH($B12,Dicembre!$B$12:$B$44,0)),INDEX(Gennaio!AK$12:AK$44,MATCH($B12,Gennaio!$B$12:$B$44,0)),INDEX(Febbraio!AK$12:AK$44,MATCH($B12,Febbraio!$B$12:$B$44,0)),INDEX(Marzo!AK$12:AK$44,MATCH($B12,Marzo!$B$12:$B$44,0)),INDEX(Aprile!AK$12:AK$44,MATCH($B12,Aprile!$B$12:$B$44,0)),INDEX(Maggio!AK$12:AK$44,MATCH($B12,Maggio!$B$12:$B$44,0)),INDEX(Giugno!AK$12:AK$44,MATCH($B12,Giugno!$B$12:$B$44,0)),INDEX(Luglio!AK$12:AK$44,MATCH($B12,Luglio!$B$12:$B$44,0))))} -> 0 | G12: {=IF(OR(ISBLANK($B12),ISBLANK($C12)),0,SUM(INDEX(Agosto!AL$12:AL$44,MATCH($B12,Agosto!$B$12:$B$44,0)),INDEX(Settembre!AL$12:AL$44,MATCH($B12,Settembre!$B$12:$B$44,0)),INDEX(Ottobre!AL$12:AL$44,MATCH($B12,Ottobre!$B$12:$B$44,0)),INDEX(Novembre!AL$12:AL$44,MATCH($B12,Novembre!$B$12:$B$44,0)),INDEX(Dicembre!AL$12:AL$44,MATCH($B12,Dicembre!$B$12:$B$44,0)),INDEX(Gennaio!AL$12:AL$44,MATCH($B12,Gennaio!$B$12:$B$44,0)),INDEX(Febbraio!AL$12:AL$44,MATCH($B12,Febbraio!$B$12:$B$44,0)),INDEX(Marzo!AL$12:AL$44,MATCH($B12,Marzo!$B$12:$B$44,0)),INDEX(Aprile!AL$12:AL$44,MATCH($B12,Aprile!$B$12:$B$44,0)),INDEX(Maggio!AL$12:AL$44,MATCH($B12,Maggio!$B$12:$B$44,0)),INDEX(Giugno!AL$12:AL$44,MATCH($B12,Giugno!$B$12:$B$44,0)),INDEX(Luglio!AL$12:AL$44,MATCH($B12,Luglio!$B$12:$B$44,0))))} -> 0 | H12: {=IF(OR(ISBLANK($B12),ISBLANK($C12)),0,SUM(INDEX(Agosto!AM$12:AM$44,MATCH($B12,Agosto!$B$12:$B$44,0)),INDEX(Settembre!AM$12:AM$44,MATCH($B12,Settembre!$B$12:$B$44,0)),INDEX(Ottobre!AM$12:AM$44,MATCH($B12,Ottobre!$B$12:$B$44,0)),INDEX(Novembre!AM$12:AM$44,MATCH($B12,Novembre!$B$12:$B$44,0)),INDEX(Dicembre!AM$12:AM$44,MATCH($B12,Dicembre!$B$12:$B$44,0)),INDEX(Gennaio!AM$12:AM$44,MATCH($B12,Gennaio!$B$12:$B$44,0)),INDEX(Febbraio!AM$12:AM$44,MATCH($B12,Febbraio!$B$12:$B$44,0)),INDEX(Marzo!AM$12:AM$44,MATCH($B12,Marzo!$B$12:$B$44,0)),INDEX(Aprile!AM$12:AM$44,MATCH($B12,Aprile!$B$12:$B$44,0)),INDEX(Maggio!AM$12:AM$44,MATCH($B12,Maggio!$B$12:$B$44,0)),INDEX(Giugno!AM$12:AM$44,MATCH($B12,Giugno!$B$12:$B$44,0)),INDEX(Luglio!AM$12:AM$44,MATCH($B12,Luglio!$B$12:$B$44,0))))} -> 7 | I12: =IF(Q10=0,0,D12/Q10) -> 0 | J12: =IF(Q10=0,0,E12/Q10) -> 0 | K12: =IF(Q10=0,0,F12/Q10) -> 0 | L12: =IF(Q10=0,0,G12/Q10) -> 0 | M12: =IF(Q10=0,0,H12/Q10) -> 0
B13: 2 | D13: {=IF(OR(ISBLANK($B13),ISBLANK($C13)),0,SUM(INDEX(Agosto!AI$12:AI$44,MATCH($B13,Agosto!$B$12:$B$44,0)),INDEX(Settembre!AI$12:AI$44,MATCH($B13,Settembre!$B$12:$B$44,0)),INDEX(Ottobre!AI$12:AI$44,MATCH($B13,Ottobre!$B$12:$B$44,0)),INDEX(Novembre!AI$12:AI$44,MATCH($B13,Novembre!$B$12:$B$44,0)),INDEX(Dicembre!AI$12:AI$44,MATCH($B13,Dicembre!$B$12:$B$44,0)),INDEX(Gennaio!AI$12:AI$44,MATCH($B13,Gennaio!$B$12:$B$44,0)),INDEX(Febbraio!AI$12:AI$44,MATCH($B13,Febbraio!$B$12:$B$44,0)),INDEX(Marzo!AI$12:AI$44,MATCH($B13,Marzo!$B$12:$B$44,0)),INDEX(Aprile!AI$12:AI$44,MATCH($B13,Aprile!$B$12:$B$44,0)),INDEX(Maggio!AI$12:AI$44,MATCH($B13,Maggio!$B$12:$B$44,0)),INDEX(Giugno!AI$12:AI$44,MATCH($B13,Giugno!$B$12:$B$44,0)),INDEX(Luglio!AI$12:AI$44,MATCH($B13,Luglio!$B$12:$B$44,0))))} -> 6 | E13: {=IF(OR(ISBLANK($B13),ISBLANK($C13)),0,SUM(INDEX(Agosto!AJ$12:AJ$44,MATCH($B13,Agosto!$B$12:$B$44,0)),INDEX(Settembre!AJ$12:AJ$44,MATCH($B13,Settembre!$B$12:$B$44,0)),INDEX(Ottobre!AJ$12:AJ$44,MATCH($B13,Ottobre!$B$12:$B$44,0)),INDEX(Novembre!AJ$12:AJ$44,MATCH($B13,Novembre!$B$12:$B$44,0)),INDEX(Dicembre!AJ$12:AJ$44,MATCH($B13,Dicembre!$B$12:$B$44,0)),INDEX(Gennaio!AJ$12:AJ$44,MATCH($B13,Gennaio!$B$12:$B$44,0)),INDEX(Febbraio!AJ$12:AJ$44,MATCH($B13,Febbraio!$B$12:$B$44,0)),INDEX(Marzo!AJ$12:AJ$44,MATCH($B13,Marzo!$B$12:$B$44,0)),INDEX(Aprile!AJ$12:AJ$44,MATCH($B13,Aprile!$B$12:$B$44,0)),INDEX(Maggio!AJ$12:AJ$44,MATCH($B13,Maggio!$B$12:$B$44,0)),INDEX(Giugno!AJ$12:AJ$44,MATCH($B13,Giugno!$B$12:$B$44,0)),INDEX(Luglio!AJ$12:AJ$44,MATCH($B13,Luglio!$B$12:$B$44,0))))} -> 1 | F13: {=IF(OR(ISBLANK($B13),ISBLANK($C13)),0,SUM(INDEX(Agosto!AK$12:AK$44,MATCH($B13,Agosto!$B$12:$B$44,0)),INDEX(Settembre!AK$12:AK$44,MATCH($B13,Settembre!$B$12:$B$44,0)),INDEX(Ottobre!AK$12:AK$44,MATCH($B13,Ottobre!$B$12:$B$44,0)),INDEX(Novembre!AK$12:AK$44,MATCH($B13,Novembre!$B$12:$B$44,0)),INDEX(Dicembre!AK$12:AK$44,MATCH($B13,Dicembre!$B$12:$B$44,0)),INDEX(Gennaio!AK$12:AK$44,MATCH($B13,Gennaio!$B$12:$B$44,0)),INDEX(Febbraio!AK$12:AK$44,MATCH($B13,Febbraio!$B$12:$B$44,0)),INDEX(Marzo!AK$12:AK$44,MATCH($B13,Marzo!$B$12:$B$44,0)),INDEX(Aprile!AK$12:AK$44,MATCH($B13,Aprile!$B$12:$B$44,0)),INDEX(Maggio!AK$12:AK$44,MATCH($B13,Maggio!$B$12:$B$44,0)),INDEX(Giugno!AK$12:AK$44,MATCH($B13,Giugno!$B$12:$B$44,0)),INDEX(Luglio!AK$12:AK$44,MATCH($B13,Luglio!$B$12:$B$44,0))))} -> 0 | G13: {=IF(OR(ISBLANK($B13),ISBLANK($C13)),0,SUM(INDEX(Agosto!AL$12:AL$44,MATCH($B13,Agosto!$B$12:$B$44,0)),INDEX(Settembre!AL$12:AL$44,MATCH($B13,Settembre!$B$12:$B$44,0)),INDEX(Ottobre!AL$12:AL$44,MATCH($B13,Ottobre!$B$12:$B$44,0)),INDEX(Novembre!AL$12:AL$44,MATCH($B13,Novembre!$B$12:$B$44,0)),INDEX(Dicembre!AL$12:AL$44,MATCH($B13,Dicembre!$B$12:$B$44,0)),INDEX(Gennaio!AL$12:AL$44,MATCH($B13,Gennaio!$B$12:$B$44,0)),INDEX(Febbraio!AL$12:AL$44,MATCH($B13,Febbraio!$B$12:$B$44,0)),INDEX(Marzo!AL$12:AL$44,MATCH($B13,Marzo!$B$12:$B$44,0)),INDEX(Aprile!AL$12:AL$44,MATCH($B13,Aprile!$B$12:$B$44,0)),INDEX(Maggio!AL$12:AL$44,MATCH($B13,Maggio!$B$12:$B$44,0)),INDEX(Giugno!AL$12:AL$44,MATCH($B13,Giugno!$B$12:$B$44,0)),INDEX(Luglio!AL$12:AL$44,MATCH($B13,Luglio!$B$12:$B$44,0))))} -> 0 | H13: {=IF(OR(ISBLANK($B13),ISBLANK($C13)),0,SUM(INDEX(Agosto!AM$12:AM$44,MATCH($B13,Agosto!$B$12:$B$44,0)),INDEX(Settembre!AM$12:AM$44,MATCH($B13,Settembre!$B$12:$B$44,0)),INDEX(Ottobre!AM$12:AM$44,MATCH($B13,Ottobre!$B$12:$B$44,0)),INDEX(Novembre!AM$12:AM$44,MATCH($B13,Novembre!$B$12:$B$44,0)),INDEX(Dicembre!AM$12:AM$44,MATCH($B13,Dicembre!$B$12:$B$44,0)),INDEX(Gennaio!AM$12:AM$44,MATCH($B13,Gennaio!$B$12:$B$44,0)),INDEX(Febbraio!AM$12:AM$44,MATCH($B13,Febbraio!$B$12:$B$44,0)),INDEX(Marzo!AM$12:AM$44,MATCH($B13,Marzo!$B$12:$B$44,0)),INDEX(Aprile!AM$12:AM$44,MATCH($B13,Aprile!$B$12:$B$44,0)),INDEX(Maggio!AM$12:AM$44,MATCH($B13,Maggio!$B$12:$B$44,0)),INDEX(Giugno!AM$12:AM$44,MATCH($B13,Giugno!$B$12:$B$44,0)),INDEX(Luglio!AM$12:AM$44,MATCH($B13,Luglio!$B$12:$B$44,0))))} -> 0 | I13: =IF(Q10=0,0,D13/Q10) -> 0 | J13: =IF(Q10=0,0,E13/Q10) -> 0 | K13: =IF(Q10=0,0,F13/Q10) -> 0 | L13: =IF(Q10=0,0,G13/Q10) -> 0 | M13: =IF(Q10=0,0,H13/Q10) -> 0
B14: 3 | D14: =IF(OR(ISBLANK($B14),ISBLANK($C14)),0,SUM(INDEX(Agosto!AI$12:AI$44,MATCH($B14,Agosto!$B$12:$B$44,0)),INDEX(Settembre!AI$12:AI$44,MATCH($B14,Settembre!$B$12:$B$44,0)),INDEX(Ottobre!AI$12:AI$44,MATCH($B14,Ottobre!$B$12:$B$44,0)),INDEX(Novembre!AI$12:AI$44,MATCH($B14,Novembre!$B$12:$B$44,0)),INDEX(Dicembre!AI$12:AI$44,MATCH($B14,Dicembre!$B$12:$B$44,0)),INDEX(Gennaio!AI$12:AI$44,MATCH($B14,Gennaio!$B$12:$B$44,0)),INDEX(Febbraio!AI$12:AI$44,MATCH($B14,Febbraio!$B$12:$B$44,0)),INDEX(Marzo!AI$12:AI$44,MATCH($B14,Marzo!$B$12:$B$44,0)),INDEX(Aprile!AI$12:AI$44,MATCH($B14,Aprile!$B$12:$B$44,0)),INDEX(Maggio!AI$12:AI$44,MATCH($B14,Maggio!$B$12:$B$44,0)),INDEX(Giugno!AI$12:AI$44,MATCH($B14,Giugno!$B$12:$B$44,0)),INDEX(Luglio!AI$12:AI$44,MATCH($B14,Luglio!$B$12:$B$44,0)))) -> 0 | E14: =IF(OR(ISBLANK($B14),ISBLANK($C14)),0,SUM(INDEX(Agosto!AJ$12:AJ$44,MATCH($B14,Agosto!$B$12:$B$44,0)),INDEX(Settembre!AJ$12:AJ$44,MATCH($B14,Settembre!$B$12:$B$44,0)),INDEX(Ottobre!AJ$12:AJ$44,MATCH($B14,Ottobre!$B$12:$B$44,0)),INDEX(Novembre!AJ$12:AJ$44,MATCH($B14,Novembre!$B$12:$B$44,0)),INDEX(Dicembre!AJ$12:AJ$44,MATCH($B14,Dicembre!$B$12:$B$44,0)),INDEX(Gennaio!AJ$12:AJ$44,MATCH($B14,Gennaio!$B$12:$B$44,0)),INDEX(Febbraio!AJ$12:AJ$44,MATCH($B14,Febbraio!$B$12:$B$44,0)),INDEX(Marzo!AJ$12:AJ$44,MATCH($B14,Marzo!$B$12:$B$44,0)),INDEX(Aprile!AJ$12:AJ$44,MATCH($B14,Aprile!$B$12:$B$44,0)),INDEX(Maggio!AJ$12:AJ$44,MATCH($B14,Maggio!$B$12:$B$44,0)),INDEX(Giugno!AJ$12:AJ$44,MATCH($B14,Giugno!$B$12:$B$44,0)),INDEX(Luglio!AJ$12:AJ$44,MATCH($B14,Luglio!$B$12:$B$44,0)))) -> 0 | F14: =IF(OR(ISBLANK($B14),ISBLANK($C14)),0,SUM(INDEX(Agosto!AK$12:AK$44,MATCH($B14,Agosto!$B$12:$B$44,0)),INDEX(Settembre!AK$12:AK$44,MATCH($B14,Settembre!$B$12:$B$44,0)),INDEX(Ottobre!AK$12:AK$44,MATCH($B14,Ottobre!$B$12:$B$44,0)),INDEX(Novembre!AK$12:AK$44,MATCH($B14,Novembre!$B$12:$B$44,0)),INDEX(Dicembre!AK$12:AK$44,MATCH($B14,Dicembre!$B$12:$B$44,0)),INDEX(Gennaio!AK$12:AK$44,MATCH($B14,Gennaio!$B$12:$B$44,0)),INDEX(Febbraio!AK$12:AK$44,MATCH($B14,Febbraio!$B$12:$B$44,0)),INDEX(Marzo!AK$12:AK$44,MATCH($B14,Marzo!$B$12:$B$44,0)),INDEX(Aprile!AK$12:AK$44,MATCH($B14,Aprile!$B$12:$B$44,0)),INDEX(Maggio!AK$12:AK$44,MATCH($B14,Maggio!$B$12:$B$44,0)),INDEX(Giugno!AK$12:AK$44,MATCH($B14,Giugno!$B$12:$B$44,0)),INDEX(Luglio!AK$12:AK$44,MATCH($B14,Luglio!$B$12:$B$44,0)))) -> 0 | G14: =IF(OR(ISBLANK($B14),ISBLANK($C14)),0,SUM(INDEX(Agosto!AL$12:AL$44,MATCH($B14,Agosto!$B$12:$B$44,0)),INDEX(Settembre!AL$12:AL$44,MATCH($B14,Settembre!$B$12:$B$44,0)),INDEX(Ottobre!AL$12:AL$44,MATCH($B14,Ottobre!$B$12:$B$44,0)),INDEX(Novembre!AL$12:AL$44,MATCH($B14,Novembre!$B$12:$B$44,0)),INDEX(Dicembre!AL$12:AL$44,MATCH($B14,Dicembre!$B$12:$B$44,0)),INDEX(Gennaio!AL$12:AL$44,MATCH($B14,Gennaio!$B$12:$B$44,0)),INDEX(Febbraio!AL$12:AL$44,MATCH($B14,Febbraio!$B$12:$B$44,0)),INDEX(Marzo!AL$12:AL$44,MATCH($B14,Marzo!$B$12:$B$44,0)),INDEX(Aprile!AL$12:AL$44,MATCH($B14,Aprile!$B$12:$B$44,0)),INDEX(Maggio!AL$12:AL$44,MATCH($B14,Maggio!$B$12:$B$44,0)),INDEX(Giugno!AL$12:AL$44,MATCH($B14,Giugno!$B$12:$B$44,0)),INDEX(Luglio!AL$12:AL$44,MATCH($B14,Luglio!$B$12:$B$44,0)))) -> 0 | H14: =IF(OR(ISBLANK($B14),ISBLANK($C14)),0,SUM(INDEX(Agosto!AM$12:AM$44,MATCH($B14,Agosto!$B$12:$B$44,0)),INDEX(Settembre!AM$12:AM$44,MATCH($B14,Settembre!$B$12:$B$44,0)),INDEX(Ottobre!AM$12:AM$44,MATCH($B14,Ottobre!$B$12:$B$44,0)),INDEX(Novembre!AM$12:AM$44,MATCH($B14,Novembre!$B$12:$B$44,0)),INDEX(Dicembre!AM$12:AM$44,MATCH($B14,Dicembre!$B$12:$B$44,0)),INDEX(Gennaio!AM$12:AM$44,MATCH($B14,Gennaio!$B$12:$B$44,0)),INDEX(Febbraio!AM$12:AM$44,MATCH($B14,Febbraio!$B$12:$B$44,0)),INDEX(Marzo!AM$12:AM$44,MATCH($B14,Marzo!$B$12:$B$44,0)),INDEX(Aprile!AM$12:AM$44,MATCH($B14,Aprile!$B$12:$B$44,0)),INDEX(Maggio!AM$12:AM$44,MATCH($B14,Maggio!$B$12:$B$44,0)),INDEX(Giugno!AM$12:AM$44,MATCH($B14,Giugno!$B$12:$B$44,0)),INDEX(Luglio!AM$12:AM$44,MATCH($B14,Luglio!$B$12:$B$44,0)))) -> 0 | I14: =IF(Q10=0,0,D14/Q10) -> 0 | J14: =IF(Q10=0,0,E14/Q10) -> 0 | K14: =IF(Q10=0,0,F14/Q10) -> 0 | L14: =IF(Q10=0,0,G14/Q10) -> 0 | M14: =IF(Q10=0,0,H14/Q10) -> 0
B15: 4 | D15: =IF(OR(ISBLANK($B15),ISBLANK($C15)),0,SUM(INDEX(Agosto!AI$12:AI$44,MATCH($B15,Agosto!$B$12:$B$44,0)),INDEX(Settembre!AI$12:AI$44,MATCH($B15,Settembre!$B$12:$B$44,0)),INDEX(Ottobre!AI$12:AI$44,MATCH($B15,Ottobre!$B$12:$B$44,0)),INDEX(Novembre!AI$12:AI$44,MATCH($B15,Novembre!$B$12:$B$44,0)),INDEX(Dicembre!AI$12:AI$44,MATCH($B15,Dicembre!$B$12:$B$44,0)),INDEX(Gennaio!AI$12:AI$44,MATCH($B15,Gennaio!$B$12:$B$44,0)),INDEX(Febbraio!AI$12:AI$44,MATCH($B15,Febbraio!$B$12:$B$44,0)),INDEX(Marzo!AI$12:AI$44,MATCH($B15,Marzo!$B$12:$B$44,0)),INDEX(Aprile!AI$12:AI$44,MATCH($B15,Aprile!$B$12:$B$44,0)),INDEX(Maggio!AI$12:AI$44,MATCH($B15,Maggio!$B$12:$B$44,0)),INDEX(Giugno!AI$12:AI$44,MATCH($B15,Giugno!$B$12:$B$44,0)),INDEX(Luglio!AI$12:AI$44,MATCH($B15,Luglio!$B$12:$B$44,0)))) -> 0 | E15: =IF(OR(ISBLANK($B15),ISBLANK($C15)),0,SUM(INDEX(Agosto!AJ$12:AJ$44,MATCH($B15,Agosto!$B$12:$B$44,0)),INDEX(Settembre!AJ$12:AJ$44,MATCH($B15,Settembre!$B$12:$B$44,0)),INDEX(Ottobre!AJ$12:AJ$44,MATCH($B15,Ottobre!$B$12:$B$44,0)),INDEX(Novembre!AJ$12:AJ$44,MATCH($B15,Novembre!$B$12:$B$44,0)),INDEX(Dicembre!AJ$12:AJ$44,MATCH($B15,Dicembre!$B$12:$B$44,0)),INDEX(Gennaio!AJ$12:AJ$44,MATCH($B15,Gennaio!$B$12:$B$44,0)),INDEX(Febbraio!AJ$12:AJ$44,MATCH($B15,Febbraio!$B$12:$B$44,0)),INDEX(Marzo!AJ$12:AJ$44,MATCH($B15,Marzo!$B$12:$B$44,0)),INDEX(Aprile!AJ$12:AJ$44,MATCH($B15,Aprile!$B$12:$B$44,0)),INDEX(Maggio!AJ$12:AJ$44,MATCH($B15,Maggio!$B$12:$B$44,0)),INDEX(Giugno!AJ$12:AJ$44,MATCH($B15,Giugno!$B$12:$B$44,0)),INDEX(Luglio!AJ$12:AJ$44,MATCH($B15,Luglio!$B$12:$B$44,0)))) -> 0 | F15: =IF(OR(ISBLANK($B15),ISBLANK($C15)),0,SUM(INDEX(Agosto!AK$12:AK$44,MATCH($B15,Agosto!$B$12:$B$44,0)),INDEX(Settembre!AK$12:AK$44,MATCH($B15,Settembre!$B$12:$B$44,0)),INDEX(Ottobre!AK$12:AK$44,MATCH($B15,Ottobre!$B$12:$B$44,0)),INDEX(Novembre!AK$12:AK$44,MATCH($B15,Novembre!$B$12:$B$44,0)),INDEX(Dicembre!AK$12:AK$44,MATCH($B15,Dicembre!$B$12:$B$44,0)),INDEX(Gennaio!AK$12:AK$44,MATCH($B15,Gennaio!$B$12:$B$44,0)),INDEX(Febbraio!AK$12:AK$44,MATCH($B15,Febbraio!$B$12:$B$44,0)),INDEX(Marzo!AK$12:AK$44,MATCH($B15,Marzo!$B$12:$B$44,0)),INDEX(Aprile!AK$12:AK$44,MATCH($B15,Aprile!$B$12:$B$44,0)),INDEX(Maggio!AK$12:AK$44,MATCH($B15,Maggio!$B$12:$B$44,0)),INDEX(Giugno!AK$12:AK$44,MATCH($B15,Giugno!$B$12:$B$44,0)),INDEX(Luglio!AK$12:AK$44,MATCH($B15,Luglio!$B$12:$B$44,0)))) -> 0 | G15: =IF(OR(ISBLANK($B15),ISBLANK($C15)),0,SUM(INDEX(Agosto!AL$12:AL$44,MATCH($B15,Agosto!$B$12:$B$44,0)),INDEX(Settembre!AL$12:AL$44,MATCH($B15,Settembre!$B$12:$B$44,0)),INDEX(Ottobre!AL$12:AL$44,MATCH($B15,Ottobre!$B$12:$B$44,0)),INDEX(Novembre!AL$12:AL$44,MATCH($B15,Novembre!$B$12:$B$44,0)),INDEX(Dicembre!AL$12:AL$44,MATCH($B15,Dicembre!$B$12:$B$44,0)),INDEX(Gennaio!AL$12:AL$44,MATCH($B15,Gennaio!$B$12:$B$44,0)),INDEX(Febbraio!AL$12:AL$44,MATCH($B15,Febbraio!$B$12:$B$44,0)),INDEX(Marzo!AL$12:AL$44,MATCH($B15,Marzo!$B$12:$B$44,0)),INDEX(Aprile!AL$12:AL$44,MATCH($B15,Aprile!$B$12:$B$44,0)),INDEX(Maggio!AL$12:AL$44,MATCH($B15,Maggio!$B$12:$B$44,0)),INDEX(Giugno!AL$12:AL$44,MATCH($B15,Giugno!$B$12:$B$44,0)),INDEX(Luglio!AL$12:AL$44,MATCH($B15,Luglio!$B$12:$B$44,0)))) -> 0 | H15: =IF(OR(ISBLANK($B15),ISBLANK($C15)),0,SUM(INDEX(Agosto!AM$12:AM$44,MATCH($B15,Agosto!$B$12:$B$44,0)),INDEX(Settembre!AM$12:AM$44,MATCH($B15,Settembre!$B$12:$B$44,0)),INDEX(Ottobre!AM$12:AM$44,MATCH($B15,Ottobre!$B$12:$B$44,0)),INDEX(Novembre!AM$12:AM$44,MATCH($B15,Novembre!$B$12:$B$44,0)),INDEX(Dicembre!AM$12:AM$44,MATCH($B15,Dicembre!$B$12:$B$44,0)),INDEX(Gennaio!AM$12:AM$44,MATCH($B15,Gennaio!$B$12:$B$44,0)),INDEX(Febbraio!AM$12:AM$44,MATCH($B15,Febbraio!$B$12:$B$44,0)),INDEX(Marzo!AM$12:AM$44,MATCH($B15,Marzo!$B$12:$B$44,0)),INDEX(Aprile!AM$12:AM$44,MATCH($B15,Aprile!$B$12:$B$44,0)),INDEX(Maggio!AM$12:AM$44,MATCH($B15,Maggio!$B$12:$B$44,0)),INDEX(Giugno!AM$12:AM$44,MATCH($B15,Giugno!$B$12:$B$44,0)),INDEX(Luglio!AM$12:AM$44,MATCH($B15,Luglio!$B$12:$B$44,0)))) -> 0 | I15: =IF(Q10=0,0,D15/Q10) -> 0 | J15: =IF(Q10=0,0,E15/Q10) -> 0 | K15: =IF(Q10=0,0,F15/Q10) -> 0 | L15: =IF(Q10=0,0,G15/Q10) -> 0 | M15: =IF(Q10=0,0,H15/Q10) -> 0
B16: 5 | D16: =IF(OR(ISBLANK($B16),ISBLANK($C16)),0,SUM(INDEX(Agosto!AI$12:AI$44,MATCH($B16,Agosto!$B$12:$B$44,0)),INDEX(Settembre!AI$12:AI$44,MATCH($B16,Settembre!$B$12:$B$44,0)),INDEX(Ottobre!AI$12:AI$44,MATCH($B16,Ottobre!$B$12:$B$44,0)),INDEX(Novembre!AI$12:AI$44,MATCH($B16,Novembre!$B$12:$B$44,0)),INDEX(Dicembre!AI$12:AI$44,MATCH($B16,Dicembre!$B$12:$B$44,0)),INDEX(Gennaio!AI$12:AI$44,MATCH($B16,Gennaio!$B$12:$B$44,0)),INDEX(Febbraio!AI$12:AI$44,MATCH($B16,Febbraio!$B$12:$B$44,0)),INDEX(Marzo!AI$12:AI$44,MATCH($B16,Marzo!$B$12:$B$44,0)),INDEX(Aprile!AI$12:AI$44,MATCH($B16,Aprile!$B$12:$B$44,0)),INDEX(Maggio!AI$12:AI$44,MATCH($B16,Maggio!$B$12:$B$44,0)),INDEX(Giugno!AI$12:AI$44,MATCH($B16,Giugno!$B$12:$B$44,0)),INDEX(Luglio!AI$12:AI$44,MATCH($B16,Luglio!$B$12:$B$44,0)))) -> 0 | E16: =IF(OR(ISBLANK($B16),ISBLANK($C16)),0,SUM(INDEX(Agosto!AJ$12:AJ$44,MATCH($B16,Agosto!$B$12:$B$44,0)),INDEX(Settembre!AJ$12:AJ$44,MATCH($B16,Settembre!$B$12:$B$44,0)),INDEX(Ottobre!AJ$12:AJ$44,MATCH($B16,Ottobre!$B$12:$B$44,0)),INDEX(Novembre!AJ$12:AJ$44,MATCH($B16,Novembre!$B$12:$B$44,0)),INDEX(Dicembre!AJ$12:AJ$44,MATCH($B16,Dicembre!$B$12:$B$44,0)),INDEX(Gennaio!AJ$12:AJ$44,MATCH($B16,Gennaio!$B$12:$B$44,0)),INDEX(Febbraio!AJ$12:AJ$44,MATCH($B16,Febbraio!$B$12:$B$44,0)),INDEX(Marzo!AJ$12:AJ$44,MATCH($B16,Marzo!$B$12:$B$44,0)),INDEX(Aprile!AJ$12:AJ$44,MATCH($B16,Aprile!$B$12:$B$44,0)),INDEX(Maggio!AJ$12:AJ$44,MATCH($B16,Maggio!$B$12:$B$44,0)),INDEX(Giugno!AJ$12:AJ$44,MATCH($B16,Giugno!$B$12:$B$44,0)),INDEX(Luglio!AJ$12:AJ$44,MATCH($B16,Luglio!$B$12:$B$44,0)))) -> 0 | F16: =IF(OR(ISBLANK($B16),ISBLANK($C16)),0,SUM(INDEX(Agosto!AK$12:AK$44,MATCH($B16,Agosto!$B$12:$B$44,0)),INDEX(Settembre!AK$12:AK$44,MATCH($B16,Settembre!$B$12:$B$44,0)),INDEX(Ottobre!AK$12:AK$44,MATCH($B16,Ottobre!$B$12:$B$44,0)),INDEX(Novembre!AK$12:AK$44,MATCH($B16,Novembre!$B$12:$B$44,0)),INDEX(Dicembre!AK$12:AK$44,MATCH($B16,Dicembre!$B$12:$B$44,0)),INDEX(Gennaio!AK$12:AK$44,MATCH($B16,Gennaio!$B$12:$B$44,0)),INDEX(Febbraio!AK$12:AK$44,MATCH($B16,Febbraio!$B$12:$B$44,0)),INDEX(Marzo!AK$12:AK$44,MATCH($B16,Marzo!$B$12:$B$44,0)),INDEX(Aprile!AK$12:AK$44,MATCH($B16,Aprile!$B$12:$B$44,0)),INDEX(Maggio!AK$12:AK$44,MATCH($B16,Maggio!$B$12:$B$44,0)),INDEX(Giugno!AK$12:AK$44,MATCH($B16,Giugno!$B$12:$B$44,0)),INDEX(Luglio!AK$12:AK$44,MATCH($B16,Luglio!$B$12:$B$44,0)))) -> 0 | G16: =IF(OR(ISBLANK($B16),ISBLANK($C16)),0,SUM(INDEX(Agosto!AL$12:AL$44,MATCH($B16,Agosto!$B$12:$B$44,0)),INDEX(Settembre!AL$12:AL$44,MATCH($B16,Settembre!$B$12:$B$44,0)),INDEX(Ottobre!AL$12:AL$44,MATCH($B16,Ottobre!$B$12:$B$44,0)),INDEX(Novembre!AL$12:AL$44,MATCH($B16,Novembre!$B$12:$B$44,0)),INDEX(Dicembre!AL$12:AL$44,MATCH($B16,Dicembre!$B$12:$B$44,0)),INDEX(Gennaio!AL$12:AL$44,MATCH($B16,Gennaio!$B$12:$B$44,0)),INDEX(Febbraio!AL$12:AL$44,MATCH($B16,Febbraio!$B$12:$B$44,0)),INDEX(Marzo!AL$12:AL$44,MATCH($B16,Marzo!$B$12:$B$44,0)),INDEX(Aprile!AL$12:AL$44,MATCH($B16,Aprile!$B$12:$B$44,0)),INDEX(Maggio!AL$12:AL$44,MATCH($B16,Maggio!$B$12:$B$44,0)),INDEX(Giugno!AL$12:AL$44,MATCH($B16,Giugno!$B$12:$B$44,0)),INDEX(Luglio!AL$12:AL$44,MATCH($B16,Luglio!$B$12:$B$44,0)))) -> 0 | H16: =IF(OR(ISBLANK($B16),ISBLANK($C16)),0,SUM(INDEX(Agosto!AM$12:AM$44,MATCH($B16,Agosto!$B$12:$B$44,0)),INDEX(Settembre!AM$12:AM$44,MATCH($B16,Settembre!$B$12:$B$44,0)),INDEX(Ottobre!AM$12:AM$44,MATCH($B16,Ottobre!$B$12:$B$44,0)),INDEX(Novembre!AM$12:AM$44,MATCH($B16,Novembre!$B$12:$B$44,0)),INDEX(Dicembre!AM$12:AM$44,MATCH($B16,Dicembre!$B$12:$B$44,0)),INDEX(Gennaio!AM$12:AM$44,MATCH($B16,Gennaio!$B$12:$B$44,0)),INDEX(Febbraio!AM$12:AM$44,MATCH($B16,Febbraio!$B$12:$B$44,0)),INDEX(Marzo!AM$12:AM$44,MATCH($B16,Marzo!$B$12:$B$44,0)),INDEX(Aprile!AM$12:AM$44,MATCH($B16,Aprile!$B$12:$B$44,0)),INDEX(Maggio!AM$12:AM$44,MATCH($B16,Maggio!$B$12:$B$44,0)),INDEX(Giugno!AM$12:AM$44,MATCH($B16,Giugno!$B$12:$B$44,0)),INDEX(Luglio!AM$12:AM$44,MATCH($B16,Luglio!$B$12:$B$44,0)))) -> 0 | I16: =IF(Q10=0,0,D16/Q10) -> 0 | J16: =IF(Q10=0,0,E16/Q10) -> 0 | K16: =IF(Q10=0,0,F16/Q10) -> 0 | L16: =IF(Q10=0,0,G16/Q10) -> 0 | M16: =IF(Q10=0,0,H16/Q10) -> 0
B17: 6 | D17: =IF(OR(ISBLANK($B17),ISBLANK($C17)),0,SUM(INDEX(Agosto!AI$12:AI$44,MATCH($B17,Agosto!$B$12:$B$44,0)),INDEX(Settembre!AI$12:AI$44,MATCH($B17,Settembre!$B$12:$B$44,0)),INDEX(Ottobre!AI$12:AI$44,MATCH($B17,Ottobre!$B$12:$B$44,0)),INDEX(Novembre!AI$12:AI$44,MATCH($B17,Novembre!$B$12:$B$44,0)),INDEX(Dicembre!AI$12:AI$44,MATCH($B17,Dicembre!$B$12:$B$44,0)),INDEX(Gennaio!AI$12:AI$44,MATCH($B17,Gennaio!$B$12:$B$44,0)),INDEX(Febbraio!AI$12:AI$44,MATCH($B17,Febbraio!$B$12:$B$44,0)),INDEX(Marzo!AI$12:AI$44,MATCH($B17,Marzo!$B$12:$B$44,0)),INDEX(Aprile!AI$12:AI$44,MATCH($B17,Aprile!$B$12:$B$44,0)),INDEX(Maggio!AI$12:AI$44,MATCH($B17,Maggio!$B$12:$B$44,0)),INDEX(Giugno!AI$12:AI$44,MATCH($B17,Giugno!$B$12:$B$44,0)),INDEX(Luglio!AI$12:AI$44,MATCH($B17,Luglio!$B$12:$B$44,0)))) -> 0 | E17: =IF(OR(ISBLANK($B17),ISBLANK($C17)),0,SUM(INDEX(Agosto!AJ$12:AJ$44,MATCH($B17,Agosto!$B$12:$B$44,0)),INDEX(Settembre!AJ$12:AJ$44,MATCH($B17,Settembre!$B$12:$B$44,0)),INDEX(Ottobre!AJ$12:AJ$44,MATCH($B17,Ottobre!$B$12:$B$44,0)),INDEX(Novembre!AJ$12:AJ$44,MATCH($B17,Novembre!$B$12:$B$44,0)),INDEX(Dicembre!AJ$12:AJ$44,MATCH($B17,Dicembre!$B$12:$B$44,0)),INDEX(Gennaio!AJ$12:AJ$44,MATCH($B17,Gennaio!$B$12:$B$44,0)),INDEX(Febbraio!AJ$12:AJ$44,MATCH($B17,Febbraio!$B$12:$B$44,0)),INDEX(Marzo!AJ$12:AJ$44,MATCH($B17,Marzo!$B$12:$B$44,0)),INDEX(Aprile!AJ$12:AJ$44,MATCH($B17,Aprile!$B$12:$B$44,0)),INDEX(Maggio!AJ$12:AJ$44,MATCH($B17,Maggio!$B$12:$B$44,0)),INDEX(Giugno!AJ$12:AJ$44,MATCH($B17,Giugno!$B$12:$B$44,0)),INDEX(Luglio!AJ$12:AJ$44,MATCH($B17,Luglio!$B$12:$B$44,0)))) -> 0 | F17: =IF(OR(ISBLANK($B17),ISBLANK($C17)),0,SUM(INDEX(Agosto!AK$12:AK$44,MATCH($B17,Agosto!$B$12:$B$44,0)),INDEX(Settembre!AK$12:AK$44,MATCH($B17,Settembre!$B$12:$B$44,0)),INDEX(Ottobre!AK$12:AK$44,MATCH($B17,Ottobre!$B$12:$B$44,0)),INDEX(Novembre!AK$12:AK$44,MATCH($B17,Novembre!$B$12:$B$44,0)),INDEX(Dicembre!AK$12:AK$44,MATCH($B17,Dicembre!$B$12:$B$44,0)),INDEX(Gennaio!AK$12:AK$44,MATCH($B17,Gennaio!$B$12:$B$44,0)),INDEX(Febbraio!AK$12:AK$44,MATCH($B17,Febbraio!$B$12:$B$44,0)),INDEX(Marzo!AK$12:AK$44,MATCH($B17,Marzo!$B$12:$B$44,0)),INDEX(Aprile!AK$12:AK$44,MATCH($B17,Aprile!$B$12:$B$44,0)),INDEX(Maggio!AK$12:AK$44,MATCH($B17,Maggio!$B$12:$B$44,0)),INDEX(Giugno!AK$12:AK$44,MATCH($B17,Giugno!$B$12:$B$44,0)),INDEX(Luglio!AK$12:AK$44,MATCH($B17,Luglio!$B$12:$B$44,0)))) -> 0 | G17: =IF(OR(ISBLANK($B17),ISBLANK($C17)),0,SUM(INDEX(Agosto!AL$12:AL$44,MATCH($B17,Agosto!$B$12:$B$44,0)),INDEX(Settembre!AL$12:AL$44,MATCH($B17,Settembre!$B$12:$B$44,0)),INDEX(Ottobre!AL$12:AL$44,MATCH($B17,Ottobre!$B$12:$B$44,0)),INDEX(Novembre!AL$12:AL$44,MATCH($B17,Novembre!$B$12:$B$44,0)),INDEX(Dicembre!AL$12:AL$44,MATCH($B17,Dicembre!$B$12:$B$44,0)),INDEX(Gennaio!AL$12:AL$44,MATCH($B17,Gennaio!$B$12:$B$44,0)),INDEX(Febbraio!AL$12:AL$44,MATCH($B17,Febbraio!$B$12:$B$44,0)),INDEX(Marzo!AL$12:AL$44,MATCH($B17,Marzo!$B$12:$B$44,0)),INDEX(Aprile!AL$12:AL$44,MATCH($B17,Aprile!$B$12:$B$44,0)),INDEX(Maggio!AL$12:AL$44,MATCH($B17,Maggio!$B$12:$B$44,0)),INDEX(Giugno!AL$12:AL$44,MATCH($B17,Giugno!$B$12:$B$44,0)),INDEX(Luglio!AL$12:AL$44,MATCH($B17,Luglio!$B$12:$B$44,0)))) -> 0 | H17: =IF(OR(ISBLANK($B17),ISBLANK($C17)),0,SUM(INDEX(Agosto!AM$12:AM$44,MATCH($B17,Agosto!$B$12:$B$44,0)),INDEX(Settembre!AM$12:AM$44,MATCH($B17,Settembre!$B$12:$B$44,0)),INDEX(Ottobre!AM$12:AM$44,MATCH($B17,Ottobre!$B$12:$B$44,0)),INDEX(Novembre!AM$12:AM$44,MATCH($B17,Novembre!$B$12:$B$44,0)),INDEX(Dicembre!AM$12:AM$44,MATCH($B17,Dicembre!$B$12:$B$44,0)),INDEX(Gennaio!AM$12:AM$44,MATCH($B17,Gennaio!$B$12:$B$44,0)),INDEX(Febbraio!AM$12:AM$44,MATCH($B17,Febbraio!$B$12:$B$44,0)),INDEX(Marzo!AM$12:AM$44,MATCH($B17,Marzo!$B$12:$B$44,0)),INDEX(Aprile!AM$12:AM$44,MATCH($B17,Aprile!$B$12:$B$44,0)),INDEX(Maggio!AM$12:AM$44,MATCH($B17,Maggio!$B$12:$B$44,0)),INDEX(Giugno!AM$12:AM$44,MATCH($B17,Giugno!$B$12:$B$44,0)),INDEX(Luglio!AM$12:AM$44,MATCH($B17,Luglio!$B$12:$B$44,0)))) -> 0 | I17: =IF(Q10=0,0,D17/Q10) -> 0 | J17: =IF(Q10=0,0,E17/Q10) -> 0 | K17: =IF(Q10=0,0,F17/Q10) -> 0 | L17: =IF(Q10=0,0,G17/Q10) -> 0 | M17: =IF(Q10=0,0,H17/Q10) -> 0
B18: 7 | D18: =IF(OR(ISBLANK($B18),ISBLANK($C18)),0,SUM(INDEX(Agosto!AI$12:AI$44,MATCH($B18,Agosto!$B$12:$B$44,0)),INDEX(Settembre!AI$12:AI$44,MATCH($B18,Settembre!$B$12:$B$44,0)),INDEX(Ottobre!AI$12:AI$44,MATCH($B18,Ottobre!$B$12:$B$44,0)),INDEX(Novembre!AI$12:AI$44,MATCH($B18,Novembre!$B$12:$B$44,0)),INDEX(Dicembre!AI$12:AI$44,MATCH($B18,Dicembre!$B$12:$B$44,0)),INDEX(Gennaio!AI$12:AI$44,MATCH($B18,Gennaio!$B$12:$B$44,0)),INDEX(Febbraio!AI$12:AI$44,MATCH($B18,Febbraio!$B$12:$B$44,0)),INDEX(Marzo!AI$12:AI$44,MATCH($B18,Marzo!$B$12:$B$44,0)),INDEX(Aprile!AI$12:AI$44,MATCH($B18,Aprile!$B$12:$B$44,0)),INDEX(Maggio!AI$12:AI$44,MATCH($B18,Maggio!$B$12:$B$44,0)),INDEX(Giugno!AI$12:AI$44,MATCH($B18,Giugno!$B$12:$B$44,0)),INDEX(Luglio!AI$12:AI$44,MATCH($B18,Luglio!$B$12:$B$44,0)))) -> 0 | E18: =IF(OR(ISBLANK($B18),ISBLANK($C18)),0,SUM(INDEX(Agosto!AJ$12:AJ$44,MATCH($B18,Agosto!$B$12:$B$44,0)),INDEX(Settembre!AJ$12:AJ$44,MATCH($B18,Settembre!$B$12:$B$44,0)),INDEX(Ottobre!AJ$12:AJ$44,MATCH($B18,Ottobre!$B$12:$B$44,0)),INDEX(Novembre!AJ$12:AJ$44,MATCH($B18,Novembre!$B$12:$B$44,0)),INDEX(Dicembre!AJ$12:AJ$44,MATCH($B18,Dicembre!$B$12:$B$44,0)),INDEX(Gennaio!AJ$12:AJ$44,MATCH($B18,Gennaio!$B$12:$B$44,0)),INDEX(Febbraio!AJ$12:AJ$44,MATCH($B18,Febbraio!$B$12:$B$44,0)),INDEX(Marzo!AJ$12:AJ$44,MATCH($B18,Marzo!$B$12:$B$44,0)),INDEX(Aprile!AJ$12:AJ$44,MATCH($B18,Aprile!$B$12:$B$44,0)),INDEX(Maggio!AJ$12:AJ$44,MATCH($B18,Maggio!$B$12:$B$44,0)),INDEX(Giugno!AJ$12:AJ$44,MATCH($B18,Giugno!$B$12:$B$44,0)),INDEX(Luglio!AJ$12:AJ$44,MATCH($B18,Luglio!$B$12:$B$44,0)))) -> 0 | F18: =IF(OR(ISBLANK($B18),ISBLANK($C18)),0,SUM(INDEX(Agosto!AK$12:AK$44,MATCH($B18,Agosto!$B$12:$B$44,0)),INDEX(Settembre!AK$12:AK$44,MATCH($B18,Settembre!$B$12:$B$44,0)),INDEX(Ottobre!AK$12:AK$44,MATCH($B18,Ottobre!$B$12:$B$44,0)),INDEX(Novembre!AK$12:AK$44,MATCH($B18,Novembre!$B$12:$B$44,0)),INDEX(Dicembre!AK$12:AK$44,MATCH($B18,Dicembre!$B$12:$B$44,0)),INDEX(Gennaio!AK$12:AK$44,MATCH($B18,Gennaio!$B$12:$B$44,0)),INDEX(Febbraio!AK$12:AK$44,MATCH($B18,Febbraio!$B$12:$B$44,0)),INDEX(Marzo!AK$12:AK$44,MATCH($B18,Marzo!$B$12:$B$44,0)),INDEX(Aprile!AK$12:AK$44,MATCH($B18,Aprile!$B$12:$B$44,0)),INDEX(Maggio!AK$12:AK$44,MATCH($B18,Maggio!$B$12:$B$44,0)),INDEX(Giugno!AK$12:AK$44,MATCH($B18,Giugno!$B$12:$B$44,0)),INDEX(Luglio!AK$12:AK$44,MATCH($B18,Luglio!$B$12:$B$44,0)))) -> 0 | G18: =IF(OR(ISBLANK($B18),ISBLANK($C18)),0,SUM(INDEX(Agosto!AL$12:AL$44,MATCH($B18,Agosto!$B$12:$B$44,0)),INDEX(Settembre!AL$12:AL$44,MATCH($B18,Settembre!$B$12:$B$44,0)),INDEX(Ottobre!AL$12:AL$44,MATCH($B18,Ottobre!$B$12:$B$44,0)),INDEX(Novembre!AL$12:AL$44,MATCH($B18,Novembre!$B$12:$B$44,0)),INDEX(Dicembre!AL$12:AL$44,MATCH($B18,Dicembre!$B$12:$B$44,0)),INDEX(Gennaio!AL$12:AL$44,MATCH($B18,Gennaio!$B$12:$B$44,0)),INDEX(Febbraio!AL$12:AL$44,MATCH($B18,Febbraio!$B$12:$B$44,0)),INDEX(Marzo!AL$12:AL$44,MATCH($B18,Marzo!$B$12:$B$44,0)),INDEX(Aprile!AL$12:AL$44,MATCH($B18,Aprile!$B$12:$B$44,0)),INDEX(Maggio!AL$12:AL$44,MATCH($B18,Maggio!$B$12:$B$44,0)),INDEX(Giugno!AL$12:AL$44,MATCH($B18,Giugno!$B$12:$B$44,0)),INDEX(Luglio!AL$12:AL$44,MATCH($B18,Luglio!$B$12:$B$44,0)))) -> 0 | H18: =IF(OR(ISBLANK($B18),ISBLANK($C18)),0,SUM(INDEX(Agosto!AM$12:AM$44,MATCH($B18,Agosto!$B$12:$B$44,0)),INDEX(Settembre!AM$12:AM$44,MATCH($B18,Settembre!$B$12:$B$44,0)),INDEX(Ottobre!AM$12:AM$44,MATCH($B18,Ottobre!$B$12:$B$44,0)),INDEX(Novembre!AM$12:AM$44,MATCH($B18,Novembre!$B$12:$B$44,0)),INDEX(Dicembre!AM$12:AM$44,MATCH($B18,Dicembre!$B$12:$B$44,0)),INDEX(Gennaio!AM$12:AM$44,MATCH($B18,Gennaio!$B$12:$B$44,0)),INDEX(Febbraio!AM$12:AM$44,MATCH($B18,Febbraio!$B$12:$B$44,0)),INDEX(Marzo!AM$12:AM$44,MATCH($B18,Marzo!$B$12:$B$44,0)),INDEX(Aprile!AM$12:AM$44,MATCH($B18,Aprile!$B$12:$B$44,0)),INDEX(Maggio!AM$12:AM$44,MATCH($B18,Maggio!$B$12:$B$44,0)),INDEX(Giugno!AM$12:AM$44,MATCH($B18,Giugno!$B$12:$B$44,0)),INDEX(Luglio!AM$12:AM$44,MATCH($B18,Luglio!$B$12:$B$44,0)))) -> 0 | I18: =IF(Q10=0,0,D18/Q10) -> 0 | J18: =IF(Q10=0,0,E18/Q10) -> 0 | K18: =IF(Q10=0,0,F18/Q10) -> 0 | L18: =IF(Q10=0,0,G18/Q10) -> 0 | M18: =IF(Q10=0,0,H18/Q10) -> 0
B19: 8 | D19: =IF(OR(ISBLANK($B19),ISBLANK($C19)),0,SUM(INDEX(Agosto!AI$12:AI$44,MATCH($B19,Agosto!$B$12:$B$44,0)),INDEX(Settembre!AI$12:AI$44,MATCH($B19,Settembre!$B$12:$B$44,0)),INDEX(Ottobre!AI$12:AI$44,MATCH($B19,Ottobre!$B$12:$B$44,0)),INDEX(Novembre!AI$12:AI$44,MATCH($B19,Novembre!$B$12:$B$44,0)),INDEX(Dicembre!AI$12:AI$44,MATCH($B19,Dicembre!$B$12:$B$44,0)),INDEX(Gennaio!AI$12:AI$44,MATCH($B19,Gennaio!$B$12:$B$44,0)),INDEX(Febbraio!AI$12:AI$44,MATCH($B19,Febbraio!$B$12:$B$44,0)),INDEX(Marzo!AI$12:AI$44,MATCH($B19,Marzo!$B$12:$B$44,0)),INDEX(Aprile!AI$12:AI$44,MATCH($B19,Aprile!$B$12:$B$44,0)),INDEX(Maggio!AI$12:AI$44,MATCH($B19,Maggio!$B$12:$B$44,0)),INDEX(Giugno!AI$12:AI$44,MATCH($B19,Giugno!$B$12:$B$44,0)),INDEX(Luglio!AI$12:AI$44,MATCH($B19,Luglio!$B$12:$B$44,0)))) -> 0 | E19: =IF(OR(ISBLANK($B19),ISBLANK($C19)),0,SUM(INDEX(Agosto!AJ$12:AJ$44,MATCH($B19,Agosto!$B$12:$B$44,0)),INDEX(Settembre!AJ$12:AJ$44,MATCH($B19,Settembre!$B$12:$B$44,0)),INDEX(Ottobre!AJ$12:AJ$44,MATCH($B19,Ottobre!$B$12:$B$44,0)),INDEX(Novembre!AJ$12:AJ$44,MATCH($B19,Novembre!$B$12:$B$44,0)),INDEX(Dicembre!AJ$12:AJ$44,MATCH($B19,Dicembre!$B$12:$B$44,0)),INDEX(Gennaio!AJ$12:AJ$44,MATCH($B19,Gennaio!$B$12:$B$44,0)),INDEX(Febbraio!AJ$12:AJ$44,MATCH($B19,Febbraio!$B$12:$B$44,0)),INDEX(Marzo!AJ$12:AJ$44,MATCH($B19,Marzo!$B$12:$B$44,0)),INDEX(Aprile!AJ$12:AJ$44,MATCH($B19,Aprile!$B$12:$B$44,0)),INDEX(Maggio!AJ$12:AJ$44,MATCH($B19,Maggio!$B$12:$B$44,0)),INDEX(Giugno!AJ$12:AJ$44,MATCH($B19,Giugno!$B$12:$B$44,0)),INDEX(Luglio!AJ$12:AJ$44,MATCH($B19,Luglio!$B$12:$B$44,0)))) -> 0 | F19: =IF(OR(ISBLANK($B19),ISBLANK($C19)),0,SUM(INDEX(Agosto!AK$12:AK$44,MATCH($B19,Agosto!$B$12:$B$44,0)),INDEX(Settembre!AK$12:AK$44,MATCH($B19,Settembre!$B$12:$B$44,0)),INDEX(Ottobre!AK$12:AK$44,MATCH($B19,Ottobre!$B$12:$B$44,0)),INDEX(Novembre!AK$12:AK$44,MATCH($B19,Novembre!$B$12:$B$44,0)),INDEX(Dicembre!AK$12:AK$44,MATCH($B19,Dicembre!$B$12:$B$44,0)),INDEX(Gennaio!AK$12:AK$44,MATCH($B19,Gennaio!$B$12:$B$44,0)),INDEX(Febbraio!AK$12:AK$44,MATCH($B19,Febbraio!$B$12:$B$44,0)),INDEX(Marzo!AK$12:AK$44,MATCH($B19,Marzo!$B$12:$B$44,0)),INDEX(Aprile!AK$12:AK$44,MATCH($B19,Aprile!$B$12:$B$44,0)),INDEX(Maggio!AK$12:AK$44,MATCH($B19,Maggio!$B$12:$B$44,0)),INDEX(Giugno!AK$12:AK$44,MATCH($B19,Giugno!$B$12:$B$44,0)),INDEX(Luglio!AK$12:AK$44,MATCH($B19,Luglio!$B$12:$B$44,0)))) -> 0 | G19: =IF(OR(ISBLANK($B19),ISBLANK($C19)),0,SUM(INDEX(Agosto!AL$12:AL$44,MATCH($B19,Agosto!$B$12:$B$44,0)),INDEX(Settembre!AL$12:AL$44,MATCH($B19,Settembre!$B$12:$B$44,0)),INDEX(Ottobre!AL$12:AL$44,MATCH($B19,Ottobre!$B$12:$B$44,0)),INDEX(Novembre!AL$12:AL$44,MATCH($B19,Novembre!$B$12:$B$44,0)),INDEX(Dicembre!AL$12:AL$44,MATCH($B19,Dicembre!$B$12:$B$44,0)),INDEX(Gennaio!AL$12:AL$44,MATCH($B19,Gennaio!$B$12:$B$44,0)),INDEX(Febbraio!AL$12:AL$44,MATCH($B19,Febbraio!$B$12:$B$44,0)),INDEX(Marzo!AL$12:AL$44,MATCH($B19,Marzo!$B$12:$B$44,0)),INDEX(Aprile!AL$12:AL$44,MATCH($B19,Aprile!$B$12:$B$44,0)),INDEX(Maggio!AL$12:AL$44,MATCH($B19,Maggio!$B$12:$B$44,0)),INDEX(Giugno!AL$12:AL$44,MATCH($B19,Giugno!$B$12:$B$44,0)),INDEX(Luglio!AL$12:AL$44,MATCH($B19,Luglio!$B$12:$B$44,0)))) -> 0 | H19: =IF(OR(ISBLANK($B19),ISBLANK($C19)),0,SUM(INDEX(Agosto!AM$12:AM$44,MATCH($B19,Agosto!$B$12:$B$44,0)),INDEX(Settembre!AM$12:AM$44,MATCH($B19,Settembre!$B$12:$B$44,0)),INDEX(Ottobre!AM$12:AM$44,MATCH($B19,Ottobre!$B$12:$B$44,0)),INDEX(Novembre!AM$12:AM$44,MATCH($B19,Novembre!$B$12:$B$44,0)),INDEX(Dicembre!AM$12:AM$44,MATCH($B19,Dicembre!$B$12:$B$44,0)),INDEX(Gennaio!AM$12:AM$44,MATCH($B19,Gennaio!$B$12:$B$44,0)),INDEX(Febbraio!AM$12:AM$44,MATCH($B19,Febbraio!$B$12:$B$44,0)),INDEX(Marzo!AM$12:AM$44,MATCH($B19,Marzo!$B$12:$B$44,0)),INDEX(Aprile!AM$12:AM$44,MATCH($B19,Aprile!$B$12:$B$44,0)),INDEX(Maggio!AM$12:AM$44,MATCH($B19,Maggio!$B$12:$B$44,0)),INDEX(Giugno!AM$12:AM$44,MATCH($B19,Giugno!$B$12:$B$44,0)),INDEX(Luglio!AM$12:AM$44,MATCH($B19,Luglio!$B$12:$B$44,0)))) -> 0 | I19: =IF(Q10=0,0,D19/Q10) -> 0 | J19: =IF(Q10=0,0,E19/Q10) -> 0 | K19: =IF(Q10=0,0,F19/Q10) -> 0 | L19: =IF(Q10=0,0,G19/Q10) -> 0 | M19: =IF(Q10=0,0,H19/Q10) -> 0
B20: 9 | D20: =IF(OR(ISBLANK($B20),ISBLANK($C20)),0,SUM(INDEX(Agosto!AI$12:AI$44,MATCH($B20,Agosto!$B$12:$B$44,0)),INDEX(Settembre!AI$12:AI$44,MATCH($B20,Settembre!$B$12:$B$44,0)),INDEX(Ottobre!AI$12:AI$44,MATCH($B20,Ottobre!$B$12:$B$44,0)),INDEX(Novembre!AI$12:AI$44,MATCH($B20,Novembre!$B$12:$B$44,0)),INDEX(Dicembre!AI$12:AI$44,MATCH($B20,Dicembre!$B$12:$B$44,0)),INDEX(Gennaio!AI$12:AI$44,MATCH($B20,Gennaio!$B$12:$B$44,0)),INDEX(Febbraio!AI$12:AI$44,MATCH($B20,Febbraio!$B$12:$B$44,0)),INDEX(Marzo!AI$12:AI$44,MATCH($B20,Marzo!$B$12:$B$44,0)),INDEX(Aprile!AI$12:AI$44,MATCH($B20,Aprile!$B$12:$B$44,0)),INDEX(Maggio!AI$12:AI$44,MATCH($B20,Maggio!$B$12:$B$44,0)),INDEX(Giugno!AI$12:AI$44,MATCH($B20,Giugno!$B$12:$B$44,0)),INDEX(Luglio!AI$12:AI$44,MATCH($B20,Luglio!$B$12:$B$44,0)))) -> 0 | E20: =IF(OR(ISBLANK($B20),ISBLANK($C20)),0,SUM(INDEX(Agosto!AJ$12:AJ$44,MATCH($B20,Agosto!$B$12:$B$44,0)),INDEX(Settembre!AJ$12:AJ$44,MATCH($B20,Settembre!$B$12:$B$44,0)),INDEX(Ottobre!AJ$12:AJ$44,MATCH($B20,Ottobre!$B$12:$B$44,0)),INDEX(Novembre!AJ$12:AJ$44,MATCH($B20,Novembre!$B$12:$B$44,0)),INDEX(Dicembre!AJ$12:AJ$44,MATCH($B20,Dicembre!$B$12:$B$44,0)),INDEX(Gennaio!AJ$12:AJ$44,MATCH($B20,Gennaio!$B$12:$B$44,0)),INDEX(Febbraio!AJ$12:AJ$44,MATCH($B20,Febbraio!$B$12:$B$44,0)),INDEX(Marzo!AJ$12:AJ$44,MATCH($B20,Marzo!$B$12:$B$44,0)),INDEX(Aprile!AJ$12:AJ$44,MATCH($B20,Aprile!$B$12:$B$44,0)),INDEX(Maggio!AJ$12:AJ$44,MATCH($B20,Maggio!$B$12:$B$44,0)),INDEX(Giugno!AJ$12:AJ$44,MATCH($B20,Giugno!$B$12:$B$44,0)),INDEX(Luglio!AJ$12:AJ$44,MATCH($B20,Luglio!$B$12:$B$44,0)))) -> 0 | F20: =IF(OR(ISBLANK($B20),ISBLANK($C20)),0,SUM(INDEX(Agosto!AK$12:AK$44,MATCH($B20,Agosto!$B$12:$B$44,0)),INDEX(Settembre!AK$12:AK$44,MATCH($B20,Settembre!$B$12:$B$44,0)),INDEX(Ottobre!AK$12:AK$44,MATCH($B20,Ottobre!$B$12:$B$44,0)),INDEX(Novembre!AK$12:AK$44,MATCH($B20,Novembre!$B$12:$B$44,0)),INDEX(Dicembre!AK$12:AK$44,MATCH($B20,Dicembre!$B$12:$B$44,0)),INDEX(Gennaio!AK$12:AK$44,MATCH($B20,Gennaio!$B$12:$B$44,0)),INDEX(Febbraio!AK$12:AK$44,MATCH($B20,Febbraio!$B$12:$B$44,0)),INDEX(Marzo!AK$12:AK$44,MATCH($B20,Marzo!$B$12:$B$44,0)),INDEX(Aprile!AK$12:AK$44,MATCH($B20,Aprile!$B$12:$B$44,0)),INDEX(Maggio!AK$12:AK$44,MATCH($B20,Maggio!$B$12:$B$44,0)),INDEX(Giugno!AK$12:AK$44,MATCH($B20,Giugno!$B$12:$B$44,0)),INDEX(Luglio!AK$12:AK$44,MATCH($B20,Luglio!$B$12:$B$44,0)))) -> 0 | G20: =IF(OR(ISBLANK($B20),ISBLANK($C20)),0,SUM(INDEX(Agosto!AL$12:AL$44,MATCH($B20,Agosto!$B$12:$B$44,0)),INDEX(Settembre!AL$12:AL$44,MATCH($B20,Settembre!$B$12:$B$44,0)),INDEX(Ottobre!AL$12:AL$44,MATCH($B20,Ottobre!$B$12:$B$44,0)),INDEX(Novembre!AL$12:AL$44,MATCH($B20,Novembre!$B$12:$B$44,0)),INDEX(Dicembre!AL$12:AL$44,MATCH($B20,Dicembre!$B$12:$B$44,0)),INDEX(Gennaio!AL$12:AL$44,MATCH($B20,Gennaio!$B$12:$B$44,0)),INDEX(Febbraio!AL$12:AL$44,MATCH($B20,Febbraio!$B$12:$B$44,0)),INDEX(Marzo!AL$12:AL$44,MATCH($B20,Marzo!$B$12:$B$44,0)),INDEX(Aprile!AL$12:AL$44,MATCH($B20,Aprile!$B$12:$B$44,0)),INDEX(Maggio!AL$12:AL$44,MATCH($B20,Maggio!$B$12:$B$44,0)),INDEX(Giugno!AL$12:AL$44,MATCH($B20,Giugno!$B$12:$B$44,0)),INDEX(Luglio!AL$12:AL$44,MATCH($B20,Luglio!$B$12:$B$44,0)))) -> 0 | H20: =IF(OR(ISBLANK($B20),ISBLANK($C20)),0,SUM(INDEX(Agosto!AM$12:AM$44,MATCH($B20,Agosto!$B$12:$B$44,0)),INDEX(Settembre!AM$12:AM$44,MATCH($B20,Settembre!$B$12:$B$44,0)),INDEX(Ottobre!AM$12:AM$44,MATCH($B20,Ottobre!$B$12:$B$44,0)),INDEX(Novembre!AM$12:AM$44,MATCH($B20,Novembre!$B$12:$B$44,0)),INDEX(Dicembre!AM$12:AM$44,MATCH($B20,Dicembre!$B$12:$B$44,0)),INDEX(Gennaio!AM$12:AM$44,MATCH($B20,Gennaio!$B$12:$B$44,0)),INDEX(Febbraio!AM$12:AM$44,MATCH($B20,Febbraio!$B$12:$B$44,0)),INDEX(Marzo!AM$12:AM$44,MATCH($B20,Marzo!$B$12:$B$44,0)),INDEX(Aprile!AM$12:AM$44,MATCH($B20,Aprile!$B$12:$B$44,0)),INDEX(Maggio!AM$12:AM$44,MATCH($B20,Maggio!$B$12:$B$44,0)),INDEX(Giugno!AM$12:AM$44,MATCH($B20,Giugno!$B$12:$B$44,0)),INDEX(Luglio!AM$12:AM$44,MATCH($B20,Luglio!$B$12:$B$44,0)))) -> 0 | I20: =IF(Q10=0,0,D20/Q10) -> 0 | J20: =IF(Q10=0,0,E20/Q10) -> 0 | K20: =IF(Q10=0,0,F20/Q10) -> 0 | L20: =IF(Q10=0,0,G20/Q10) -> 0 | M20: =IF(Q10=0,0,H20/Q10) -> 0
B21: 10 | D21: =IF(OR(ISBLANK($B21),ISBLANK($C21)),0,SUM(INDEX(Agosto!AI$12:AI$44,MATCH($B21,Agosto!$B$12:$B$44,0)),INDEX(Settembre!AI$12:AI$44,MATCH($B21,Settembre!$B$12:$B$44,0)),INDEX(Ottobre!AI$12:AI$44,MATCH($B21,Ottobre!$B$12:$B$44,0)),INDEX(Novembre!AI$12:AI$44,MATCH($B21,Novembre!$B$12:$B$44,0)),INDEX(Dicembre!AI$12:AI$44,MATCH($B21,Dicembre!$B$12:$B$44,0)),INDEX(Gennaio!AI$12:AI$44,MATCH($B21,Gennaio!$B$12:$B$44,0)),INDEX(Febbraio!AI$12:AI$44,MATCH($B21,Febbraio!$B$12:$B$44,0)),INDEX(Marzo!AI$12:AI$44,MATCH($B21,Marzo!$B$12:$B$44,0)),INDEX(Aprile!AI$12:AI$44,MATCH($B21,Aprile!$B$12:$B$44,0)),INDEX(Maggio!AI$12:AI$44,MATCH($B21,Maggio!$B$12:$B$44,0)),INDEX(Giugno!AI$12:AI$44,MATCH($B21,Giugno!$B$12:$B$44,0)),INDEX(Luglio!AI$12:AI$44,MATCH($B21,Luglio!$B$12:$B$44,0)))) -> 0 | E21: =IF(OR(ISBLANK($B21),ISBLANK($C21)),0,SUM(INDEX(Agosto!AJ$12:AJ$44,MATCH($B21,Agosto!$B$12:$B$44,0)),INDEX(Settembre!AJ$12:AJ$44,MATCH($B21,Settembre!$B$12:$B$44,0)),INDEX(Ottobre!AJ$12:AJ$44,MATCH($B21,Ottobre!$B$12:$B$44,0)),INDEX(Novembre!AJ$12:AJ$44,MATCH($B21,Novembre!$B$12:$B$44,0)),INDEX(Dicembre!AJ$12:AJ$44,MATCH($B21,Dicembre!$B$12:$B$44,0)),INDEX(Gennaio!AJ$12:AJ$44,MATCH($B21,Gennaio!$B$12:$B$44,0)),INDEX(Febbraio!AJ$12:AJ$44,MATCH($B21,Febbraio!$B$12:$B$44,0)),INDEX(Marzo!AJ$12:AJ$44,MATCH($B21,Marzo!$B$12:$B$44,0)),INDEX(Aprile!AJ$12:AJ$44,MATCH($B21,Aprile!$B$12:$B$44,0)),INDEX(Maggio!AJ$12:AJ$44,MATCH($B21,Maggio!$B$12:$B$44,0)),INDEX(Giugno!AJ$12:AJ$44,MATCH($B21,Giugno!$B$12:$B$44,0)),INDEX(Luglio!AJ$12:AJ$44,MATCH($B21,Luglio!$B$12:$B$44,0)))) -> 0 | F21: =IF(OR(ISBLANK($B21),ISBLANK($C21)),0,SUM(INDEX(Agosto!AK$12:AK$44,MATCH($B21,Agosto!$B$12:$B$44,0)),INDEX(Settembre!AK$12:AK$44,MATCH($B21,Settembre!$B$12:$B$44,0)),INDEX(Ottobre!AK$12:AK$44,MATCH($B21,Ottobre!$B$12:$B$44,0)),INDEX(Novembre!AK$12:AK$44,MATCH($B21,Novembre!$B$12:$B$44,0)),INDEX(Dicembre!AK$12:AK$44,MATCH($B21,Dicembre!$B$12:$B$44,0)),INDEX(Gennaio!AK$12:AK$44,MATCH($B21,Gennaio!$B$12:$B$44,0)),INDEX(Febbraio!AK$12:AK$44,MATCH($B21,Febbraio!$B$12:$B$44,0)),INDEX(Marzo!AK$12:AK$44,MATCH($B21,Marzo!$B$12:$B$44,0)),INDEX(Aprile!AK$12:AK$44,MATCH($B21,Aprile!$B$12:$B$44,0)),INDEX(Maggio!AK$12:AK$44,MATCH($B21,Maggio!$B$12:$B$44,0)),INDEX(Giugno!AK$12:AK$44,MATCH($B21,Giugno!$B$12:$B$44,0)),INDEX(Luglio!AK$12:AK$44,MATCH($B21,Luglio!$B$12:$B$44,0)))) -> 0 | G21: =IF(OR(ISBLANK($B21),ISBLANK($C21)),0,SUM(INDEX(Agosto!AL$12:AL$44,MATCH($B21,Agosto!$B$12:$B$44,0)),INDEX(Settembre!AL$12:AL$44,MATCH($B21,Settembre!$B$12:$B$44,0)),INDEX(Ottobre!AL$12:AL$44,MATCH($B21,Ottobre!$B$12:$B$44,0)),INDEX(Novembre!AL$12:AL$44,MATCH($B21,Novembre!$B$12:$B$44,0)),INDEX(Dicembre!AL$12:AL$44,MATCH($B21,Dicembre!$B$12:$B$44,0)),INDEX(Gennaio!AL$12:AL$44,MATCH($B21,Gennaio!$B$12:$B$44,0)),INDEX(Febbraio!AL$12:AL$44,MATCH($B21,Febbraio!$B$12:$B$44,0)),INDEX(Marzo!AL$12:AL$44,MATCH($B21,Marzo!$B$12:$B$44,0)),INDEX(Aprile!AL$12:AL$44,MATCH($B21,Aprile!$B$12:$B$44,0)),INDEX(Maggio!AL$12:AL$44,MATCH($B21,Maggio!$B$12:$B$44,0)),INDEX(Giugno!AL$12:AL$44,MATCH($B21,Giugno!$B$12:$B$44,0)),INDEX(Luglio!AL$12:AL$44,MATCH($B21,Luglio!$B$12:$B$44,0)))) -> 0 | H21: =IF(OR(ISBLANK($B21),ISBLANK($C21)),0,SUM(INDEX(Agosto!AM$12:AM$44,MATCH($B21,Agosto!$B$12:$B$44,0)),INDEX(Settembre!AM$12:AM$44,MATCH($B21,Settembre!$B$12:$B$44,0)),INDEX(Ottobre!AM$12:AM$44,MATCH($B21,Ottobre!$B$12:$B$44,0)),INDEX(Novembre!AM$12:AM$44,MATCH($B21,Novembre!$B$12:$B$44,0)),INDEX(Dicembre!AM$12:AM$44,MATCH($B21,Dicembre!$B$12:$B$44,0)),INDEX(Gennaio!AM$12:AM$44,MATCH($B21,Gennaio!$B$12:$B$44,0)),INDEX(Febbraio!AM$12:AM$44,MATCH($B21,Febbraio!$B$12:$B$44,0)),INDEX(Marzo!AM$12:AM$44,MATCH($B21,Marzo!$B$12:$B$44,0)),INDEX(Aprile!AM$12:AM$44,MATCH($B21,Aprile!$B$12:$B$44,0)),INDEX(Maggio!AM$12:AM$44,MATCH($B21,Maggio!$B$12:$B$44,0)),INDEX(Giugno!AM$12:AM$44,MATCH($B21,Giugno!$B$12:$B$44,0)),INDEX(Luglio!AM$12:AM$44,MATCH($B21,Luglio!$B$12:$B$44,0)))) -> 0 | I21: =IF(Q10=0,0,D21/Q10) -> 0 | J21: =IF(Q10=0,0,E21/Q10) -> 0 | K21: =IF(Q10=0,0,F21/Q10) -> 0 | L21: =IF(Q10=0,0,G21/Q10) -> 0 | M21: =IF(Q10=0,0,H21/Q10) -> 0
B22: 11 | D22: =IF(OR(ISBLANK($B22),ISBLANK($C22)),0,SUM(INDEX(Agosto!AI$12:AI$44,MATCH($B22,Agosto!$B$12:$B$44,0)),INDEX(Settembre!AI$12:AI$44,MATCH($B22,Settembre!$B$12:$B$44,0)),INDEX(Ottobre!AI$12:AI$44,MATCH($B22,Ottobre!$B$12:$B$44,0)),INDEX(Novembre!AI$12:AI$44,MATCH($B22,Novembre!$B$12:$B$44,0)),INDEX(Dicembre!AI$12:AI$44,MATCH($B22,Dicembre!$B$12:$B$44,0)),INDEX(Gennaio!AI$12:AI$44,MATCH($B22,Gennaio!$B$12:$B$44,0)),INDEX(Febbraio!AI$12:AI$44,MATCH($B22,Febbraio!$B$12:$B$44,0)),INDEX(Marzo!AI$12:AI$44,MATCH($B22,Marzo!$B$12:$B$44,0)),INDEX(Aprile!AI$12:AI$44,MATCH($B22,Aprile!$B$12:$B$44,0)),INDEX(Maggio!AI$12:AI$44,MATCH($B22,Maggio!$B$12:$B$44,0)),INDEX(Giugno!AI$12:AI$44,MATCH($B22,Giugno!$B$12:$B$44,0)),INDEX(Luglio!AI$12:AI$44,MATCH($B22,Luglio!$B$12:$B$44,0)))) -> 0 | E22: =IF(OR(ISBLANK($B22),ISBLANK($C22)),0,SUM(INDEX(Agosto!AJ$12:AJ$44,MATCH($B22,Agosto!$B$12:$B$44,0)),INDEX(Settembre!AJ$12:AJ$44,MATCH($B22,Settembre!$B$12:$B$44,0)),INDEX(Ottobre!AJ$12:AJ$44,MATCH($B22,Ottobre!$B$12:$B$44,0)),INDEX(Novembre!AJ$12:AJ$44,MATCH($B22,Novembre!$B$12:$B$44,0)),INDEX(Dicembre!AJ$12:AJ$44,MATCH($B22,Dicembre!$B$12:$B$44,0)),INDEX(Gennaio!AJ$12:AJ$44,MATCH($B22,Gennaio!$B$12:$B$44,0)),INDEX(Febbraio!AJ$12:AJ$44,MATCH($B22,Febbraio!$B$12:$B$44,0)),INDEX(Marzo!AJ$12:AJ$44,MATCH($B22,Marzo!$B$12:$B$44,0)),INDEX(Aprile!AJ$12:AJ$44,MATCH($B22,Aprile!$B$12:$B$44,0)),INDEX(Maggio!AJ$12:AJ$44,MATCH($B22,Maggio!$B$12:$B$44,0)),INDEX(Giugno!AJ$12:AJ$44,MATCH($B22,Giugno!$B$12:$B$44,0)),INDEX(Luglio!AJ$12:AJ$44,MATCH($B22,Luglio!$B$12:$B$44,0)))) -> 0 | F22: =IF(OR(ISBLANK($B22),ISBLANK($C22)),0,SUM(INDEX(Agosto!AK$12:AK$44,MATCH($B22,Agosto!$B$12:$B$44,0)),INDEX(Settembre!AK$12:AK$44,MATCH($B22,Settembre!$B$12:$B$44,0)),INDEX(Ottobre!AK$12:AK$44,MATCH($B22,Ottobre!$B$12:$B$44,0)),INDEX(Novembre!AK$12:AK$44,MATCH($B22,Novembre!$B$12:$B$44,0)),INDEX(Dicembre!AK$12:AK$44,MATCH($B22,Dicembre!$B$12:$B$44,0)),INDEX(Gennaio!AK$12:AK$44,MATCH($B22,Gennaio!$B$12:$B$44,0)),INDEX(Febbraio!AK$12:AK$44,MATCH($B22,Febbraio!$B$12:$B$44,0)),INDEX(Marzo!AK$12:AK$44,MATCH($B22,Marzo!$B$12:$B$44,0)),INDEX(Aprile!AK$12:AK$44,MATCH($B22,Aprile!$B$12:$B$44,0)),INDEX(Maggio!AK$12:AK$44,MATCH($B22,Maggio!$B$12:$B$44,0)),INDEX(Giugno!AK$12:AK$44,MATCH($B22,Giugno!$B$12:$B$44,0)),INDEX(Luglio!AK$12:AK$44,MATCH($B22,Luglio!$B$12:$B$44,0)))) -> 0 | G22: =IF(OR(ISBLANK($B22),ISBLANK($C22)),0,SUM(INDEX(Agosto!AL$12:AL$44,MATCH($B22,Agosto!$B$12:$B$44,0)),INDEX(Settembre!AL$12:AL$44,MATCH($B22,Settembre!$B$12:$B$44,0)),INDEX(Ottobre!AL$12:AL$44,MATCH($B22,Ottobre!$B$12:$B$44,0)),INDEX(Novembre!AL$12:AL$44,MATCH($B22,Novembre!$B$12:$B$44,0)),INDEX(Dicembre!AL$12:AL$44,MATCH($B22,Dicembre!$B$12:$B$44,0)),INDEX(Gennaio!AL$12:AL$44,MATCH($B22,Gennaio!$B$12:$B$44,0)),INDEX(Febbraio!AL$12:AL$44,MATCH($B22,Febbraio!$B$12:$B$44,0)),INDEX(Marzo!AL$12:AL$44,MATCH($B22,Marzo!$B$12:$B$44,0)),INDEX(Aprile!AL$12:AL$44,MATCH($B22,Aprile!$B$12:$B$44,0)),INDEX(Maggio!AL$12:AL$44,MATCH($B22,Maggio!$B$12:$B$44,0)),INDEX(Giugno!AL$12:AL$44,MATCH($B22,Giugno!$B$12:$B$44,0)),INDEX(Luglio!AL$12:AL$44,MATCH($B22,Luglio!$B$12:$B$44,0)))) -> 0 | H22: =IF(OR(ISBLANK($B22),ISBLANK($C22)),0,SUM(INDEX(Agosto!AM$12:AM$44,MATCH($B22,Agosto!$B$12:$B$44,0)),INDEX(Settembre!AM$12:AM$44,MATCH($B22,Settembre!$B$12:$B$44,0)),INDEX(Ottobre!AM$12:AM$44,MATCH($B22,Ottobre!$B$12:$B$44,0)),INDEX(Novembre!AM$12:AM$44,MATCH($B22,Novembre!$B$12:$B$44,0)),INDEX(Dicembre!AM$12:AM$44,MATCH($B22,Dicembre!$B$12:$B$44,0)),INDEX(Gennaio!AM$12:AM$44,MATCH($B22,Gennaio!$B$12:$B$44,0)),INDEX(Febbraio!AM$12:AM$44,MATCH($B22,Febbraio!$B$12:$B$44,0)),INDEX(Marzo!AM$12:AM$44,MATCH($B22,Marzo!$B$12:$B$44,0)),INDEX(Aprile!AM$12:AM$44,MATCH($B22,Aprile!$B$12:$B$44,0)),INDEX(Maggio!AM$12:AM$44,MATCH($B22,Maggio!$B$12:$B$44,0)),INDEX(Giugno!AM$12:AM$44,MATCH($B22,Giugno!$B$12:$B$44,0)),INDEX(Luglio!AM$12:AM$44,MATCH($B22,Luglio!$B$12:$B$44,0)))) -> 0 | I22: =IF(Q10=0,0,D22/Q10) -> 0 | J22: =IF(Q10=0,0,E22/Q10) -> 0 | K22: =IF(Q10=0,0,F22/Q10) -> 0 | L22: =IF(Q10=0,0,G22/Q10) -> 0 | M22: =IF(Q10=0,0,H22/Q10) -> 0
B23: 12 | D23: =IF(OR(ISBLANK($B23),ISBLANK($C23)),0,SUM(INDEX(Agosto!AI$12:AI$44,MATCH($B23,Agosto!$B$12:$B$44,0)),INDEX(Settembre!AI$12:AI$44,MATCH($B23,Settembre!$B$12:$B$44,0)),INDEX(Ottobre!AI$12:AI$44,MATCH($B23,Ottobre!$B$12:$B$44,0)),INDEX(Novembre!AI$12:AI$44,MATCH($B23,Novembre!$B$12:$B$44,0)),INDEX(Dicembre!AI$12:AI$44,MATCH($B23,Dicembre!$B$12:$B$44,0)),INDEX(Gennaio!AI$12:AI$44,MATCH($B23,Gennaio!$B$12:$B$44,0)),INDEX(Febbraio!AI$12:AI$44,MATCH($B23,Febbraio!$B$12:$B$44,0)),INDEX(Marzo!AI$12:AI$44,MATCH($B23,Marzo!$B$12:$B$44,0)),INDEX(Aprile!AI$12:AI$44,MATCH($B23,Aprile!$B$12:$B$44,0)),INDEX(Maggio!AI$12:AI$44,MATCH($B23,Maggio!$B$12:$B$44,0)),INDEX(Giugno!AI$12:AI$44,MATCH($B23,Giugno!$B$12:$B$44,0)),INDEX(Luglio!AI$12:AI$44,MATCH($B23,Luglio!$B$12:$B$44,0)))) -> 0 | E23: =IF(OR(ISBLANK($B23),ISBLANK($C23)),0,SUM(INDEX(Agosto!AJ$12:AJ$44,MATCH($B23,Agosto!$B$12:$B$44,0)),INDEX(Settembre!AJ$12:AJ$44,MATCH($B23,Settembre!$B$12:$B$44,0)),INDEX(Ottobre!AJ$12:AJ$44,MATCH($B23,Ottobre!$B$12:$B$44,0)),INDEX(Novembre!AJ$12:AJ$44,MATCH($B23,Novembre!$B$12:$B$44,0)),INDEX(Dicembre!AJ$12:AJ$44,MATCH($B23,Dicembre!$B$12:$B$44,0)),INDEX(Gennaio!AJ$12:AJ$44,MATCH($B23,Gennaio!$B$12:$B$44,0)),INDEX(Febbraio!AJ$12:AJ$44,MATCH($B23,Febbraio!$B$12:$B$44,0)),INDEX(Marzo!AJ$12:AJ$44,MATCH($B23,Marzo!$B$12:$B$44,0)),INDEX(Aprile!AJ$12:AJ$44,MATCH($B23,Aprile!$B$12:$B$44,0)),INDEX(Maggio!AJ$12:AJ$44,MATCH($B23,Maggio!$B$12:$B$44,0)),INDEX(Giugno!AJ$12:AJ$44,MATCH($B23,Giugno!$B$12:$B$44,0)),INDEX(Luglio!AJ$12:AJ$44,MATCH($B23,Luglio!$B$12:$B$44,0)))) -> 0 | F23: =IF(OR(ISBLANK($B23),ISBLANK($C23)),0,SUM(INDEX(Agosto!AK$12:AK$44,MATCH($B23,Agosto!$B$12:$B$44,0)),INDEX(Settembre!AK$12:AK$44,MATCH($B23,Settembre!$B$12:$B$44,0)),INDEX(Ottobre!AK$12:AK$44,MATCH($B23,Ottobre!$B$12:$B$44,0)),INDEX(Novembre!AK$12:AK$44,MATCH($B23,Novembre!$B$12:$B$44,0)),INDEX(Dicembre!AK$12:AK$44,MATCH($B23,Dicembre!$B$12:$B$44,0)),INDEX(Gennaio!AK$12:AK$44,MATCH($B23,Gennaio!$B$12:$B$44,0)),INDEX(Febbraio!AK$12:AK$44,MATCH($B23,Febbraio!$B$12:$B$44,0)),INDEX(Marzo!AK$12:AK$44,MATCH($B23,Marzo!$B$12:$B$44,0)),INDEX(Aprile!AK$12:AK$44,MATCH($B23,Aprile!$B$12:$B$44,0)),INDEX(Maggio!AK$12:AK$44,MATCH($B23,Maggio!$B$12:$B$44,0)),INDEX(Giugno!AK$12:AK$44,MATCH($B23,Giugno!$B$12:$B$44,0)),INDEX(Luglio!AK$12:AK$44,MATCH($B23,Luglio!$B$12:$B$44,0)))) -> 0 | G23: =IF(OR(ISBLANK($B23),ISBLANK($C23)),0,SUM(INDEX(Agosto!AL$12:AL$44,MATCH($B23,Agosto!$B$12:$B$44,0)),INDEX(Settembre!AL$12:AL$44,MATCH($B23,Settembre!$B$12:$B$44,0)),INDEX(Ottobre!AL$12:AL$44,MATCH($B23,Ottobre!$B$12:$B$44,0)),INDEX(Novembre!AL$12:AL$44,MATCH($B23,Novembre!$B$12:$B$44,0)),INDEX(Dicembre!AL$12:AL$44,MATCH($B23,Dicembre!$B$12:$B$44,0)),INDEX(Gennaio!AL$12:AL$44,MATCH($B23,Gennaio!$B$12:$B$44,0)),INDEX(Febbraio!AL$12:AL$44,MATCH($B23,Febbraio!$B$12:$B$44,0)),INDEX(Marzo!AL$12:AL$44,MATCH($B23,Marzo!$B$12:$B$44,0)),INDEX(Aprile!AL$12:AL$44,MATCH($B23,Aprile!$B$12:$B$44,0)),INDEX(Maggio!AL$12:AL$44,MATCH($B23,Maggio!$B$12:$B$44,0)),INDEX(Giugno!AL$12:AL$44,MATCH($B23,Giugno!$B$12:$B$44,0)),INDEX(Luglio!AL$12:AL$44,MATCH($B23,Luglio!$B$12:$B$44,0)))) -> 0 | H23: =IF(OR(ISBLANK($B23),ISBLANK($C23)),0,SUM(INDEX(Agosto!AM$12:AM$44,MATCH($B23,Agosto!$B$12:$B$44,0)),INDEX(Settembre!AM$12:AM$44,MATCH($B23,Settembre!$B$12:$B$44,0)),INDEX(Ottobre!AM$12:AM$44,MATCH($B23,Ottobre!$B$12:$B$44,0)),INDEX(Novembre!AM$12:AM$44,MATCH($B23,Novembre!$B$12:$B$44,0)),INDEX(Dicembre!AM$12:AM$44,MATCH($B23,Dicembre!$B$12:$B$44,0)),INDEX(Gennaio!AM$12:AM$44,MATCH($B23,Gennaio!$B$12:$B$44,0)),INDEX(Febbraio!AM$12:AM$44,MATCH($B23,Febbraio!$B$12:$B$44,0)),INDEX(Marzo!AM$12:AM$44,MATCH($B23,Marzo!$B$12:$B$44,0)),INDEX(Aprile!AM$12:AM$44,MATCH($B23,Aprile!$B$12:$B$44,0)),INDEX(Maggio!AM$12:AM$44,MATCH($B23,Maggio!$B$12:$B$44,0)),INDEX(Giugno!AM$12:AM$44,MATCH($B23,Giugno!$B$12:$B$44,0)),INDEX(Luglio!AM$12:AM$44,MATCH($B23,Luglio!$B$12:$B$44,0)))) -> 0 | I23: =IF(Q10=0,0,D23/Q10) -> 0 | J23: =IF(Q10=0,0,E23/Q10) -> 0 | K23: =IF(Q10=0,0,F23/Q10) -> 0 | L23: =IF(Q10=0,0,G23/Q10) -> 0 | M23: =IF(Q10=0,0,H23/Q10) -> 0
B24: 13 | D24: =IF(OR(ISBLANK($B24),ISBLANK($C24)),0,SUM(INDEX(Agosto!AI$12:AI$44,MATCH($B24,Agosto!$B$12:$B$44,0)),INDEX(Settembre!AI$12:AI$44,MATCH($B24,Settembre!$B$12:$B$44,0)),INDEX(Ottobre!AI$12:AI$44,MATCH($B24,Ottobre!$B$12:$B$44,0)),INDEX(Novembre!AI$12:AI$44,MATCH($B24,Novembre!$B$12:$B$44,0)),INDEX(Dicembre!AI$12:AI$44,MATCH($B24,Dicembre!$B$12:$B$44,0)),INDEX(Gennaio!AI$12:AI$44,MATCH($B24,Gennaio!$B$12:$B$44,0)),INDEX(Febbraio!AI$12:AI$44,MATCH($B24,Febbraio!$B$12:$B$44,0)),INDEX(Marzo!AI$12:AI$44,MATCH($B24,Marzo!$B$12:$B$44,0)),INDEX(Aprile!AI$12:AI$44,MATCH($B24,Aprile!$B$12:$B$44,0)),INDEX(Maggio!AI$12:AI$44,MATCH($B24,Maggio!$B$12:$B$44,0)),INDEX(Giugno!AI$12:AI$44,MATCH($B24,Giugno!$B$12:$B$44,0)),INDEX(Luglio!AI$12:AI$44,MATCH($B24,Luglio!$B$12:$B$44,0)))) -> 0 | E24: =IF(OR(ISBLANK($B24),ISBLANK($C24)),0,SUM(INDEX(Agosto!AJ$12:AJ$44,MATCH($B24,Agosto!$B$12:$B$44,0)),INDEX(Settembre!AJ$12:AJ$44,MATCH($B24,Settembre!$B$12:$B$44,0)),INDEX(Ottobre!AJ$12:AJ$44,MATCH($B24,Ottobre!$B$12:$B$44,0)),INDEX(Novembre!AJ$12:AJ$44,MATCH($B24,Novembre!$B$12:$B$44,0)),INDEX(Dicembre!AJ$12:AJ$44,MATCH($B24,Dicembre!$B$12:$B$44,0)),INDEX(Gennaio!AJ$12:AJ$44,MATCH($B24,Gennaio!$B$12:$B$44,0)),INDEX(Febbraio!AJ$12:AJ$44,MATCH($B24,Febbraio!$B$12:$B$44,0)),INDEX(Marzo!AJ$12:AJ$44,MATCH($B24,Marzo!$B$12:$B$44,0)),INDEX(Aprile!AJ$12:AJ$44,MATCH($B24,Aprile!$B$12:$B$44,0)),INDEX(Maggio!AJ$12:AJ$44,MATCH($B24,Maggio!$B$12:$B$44,0)),INDEX(Giugno!AJ$12:AJ$44,MATCH($B24,Giugno!$B$12:$B$44,0)),INDEX(Luglio!AJ$12:AJ$44,MATCH($B24,Luglio!$B$12:$B$44,0)))) -> 0 | F24: =IF(OR(ISBLANK($B24),ISBLANK($C24)),0,SUM(INDEX(Agosto!AK$12:AK$44,MATCH($B24,Agosto!$B$12:$B$44,0)),INDEX(Settembre!AK$12:AK$44,MATCH($B24,Settembre!$B$12:$B$44,0)),INDEX(Ottobre!AK$12:AK$44,MATCH($B24,Ottobre!$B$12:$B$44,0)),INDEX(Novembre!AK$12:AK$44,MATCH($B24,Novembre!$B$12:$B$44,0)),INDEX(Dicembre!AK$12:AK$44,MATCH($B24,Dicembre!$B$12:$B$44,0)),INDEX(Gennaio!AK$12:AK$44,MATCH($B24,Gennaio!$B$12:$B$44,0)),INDEX(Febbraio!AK$12:AK$44,MATCH($B24,Febbraio!$B$12:$B$44,0)),INDEX(Marzo!AK$12:AK$44,MATCH($B24,Marzo!$B$12:$B$44,0)),INDEX(Aprile!AK$12:AK$44,MATCH($B24,Aprile!$B$12:$B$44,0)),INDEX(Maggio!AK$12:AK$44,MATCH($B24,Maggio!$B$12:$B$44,0)),INDEX(Giugno!AK$12:AK$44,MATCH($B24,Giugno!$B$12:$B$44,0)),INDEX(Luglio!AK$12:AK$44,MATCH($B24,Luglio!$B$12:$B$44,0)))) -> 0 | G24: =IF(OR(ISBLANK($B24),ISBLANK($C24)),0,SUM(INDEX(Agosto!AL$12:AL$44,MATCH($B24,Agosto!$B$12:$B$44,0)),INDEX(Settembre!AL$12:AL$44,MATCH($B24,Settembre!$B$12:$B$44,0)),INDEX(Ottobre!AL$12:AL$44,MATCH($B24,Ottobre!$B$12:$B$44,0)),INDEX(Novembre!AL$12:AL$44,MATCH($B24,Novembre!$B$12:$B$44,0)),INDEX(Dicembre!AL$12:AL$44,MATCH($B24,Dicembre!$B$12:$B$44,0)),INDEX(Gennaio!AL$12:AL$44,MATCH($B24,Gennaio!$B$12:$B$44,0)),INDEX(Febbraio!AL$12:AL$44,MATCH($B24,Febbraio!$B$12:$B$44,0)),INDEX(Marzo!AL$12:AL$44,MATCH($B24,Marzo!$B$12:$B$44,0)),INDEX(Aprile!AL$12:AL$44,MATCH($B24,Aprile!$B$12:$B$44,0)),INDEX(Maggio!AL$12:AL$44,MATCH($B24,Maggio!$B$12:$B$44,0)),INDEX(Giugno!AL$12:AL$44,MATCH($B24,Giugno!$B$12:$B$44,0)),INDEX(Luglio!AL$12:AL$44,MATCH($B24,Luglio!$B$12:$B$44,0)))) -> 0 | H24: =IF(OR(ISBLANK($B24),ISBLANK($C24)),0,SUM(INDEX(Agosto!AM$12:AM$44,MATCH($B24,Agosto!$B$12:$B$44,0)),INDEX(Settembre!AM$12:AM$44,MATCH($B24,Settembre!$B$12:$B$44,0)),INDEX(Ottobre!AM$12:AM$44,MATCH($B24,Ottobre!$B$12:$B$44,0)),INDEX(Novembre!AM$12:AM$44,MATCH($B24,Novembre!$B$12:$B$44,0)),INDEX(Dicembre!AM$12:AM$44,MATCH($B24,Dicembre!$B$12:$B$44,0)),INDEX(Gennaio!AM$12:AM$44,MATCH($B24,Gennaio!$B$12:$B$44,0)),INDEX(Febbraio!AM$12:AM$44,MATCH($B24,Febbraio!$B$12:$B$44,0)),INDEX(Marzo!AM$12:AM$44,MATCH($B24,Marzo!$B$12:$B$44,0)),INDEX(Aprile!AM$12:AM$44,MATCH($B24,Aprile!$B$12:$B$44,0)),INDEX(Maggio!AM$12:AM$44,MATCH($B24,Maggio!$B$12:$B$44,0)),INDEX(Giugno!AM$12:AM$44,MATCH($B24,Giugno!$B$12:$B$44,0)),INDEX(Luglio!AM$12:AM$44,MATCH($B24,Luglio!$B$12:$B$44,0)))) -> 0 | I24: =IF(Q10=0,0,D24/Q10) -> 0 | J24: =IF(Q10=0,0,E24/Q10) -> 0 | K24: =IF(Q10=0,0,F24/Q10) -> 0 | L24: =IF(Q10=0,0,G24/Q10) -> 0 | M24: =IF(Q10=0,0,H24/Q10) -> 0
B25: 14 | D25: =IF(OR(ISBLANK($B25),ISBLANK($C25)),0,SUM(INDEX(Agosto!AI$12:AI$44,MATCH($B25,Agosto!$B$12:$B$44,0)),INDEX(Settembre!AI$12:AI$44,MATCH($B25,Settembre!$B$12:$B$44,0)),INDEX(Ottobre!AI$12:AI$44,MATCH($B25,Ottobre!$B$12:$B$44,0)),INDEX(Novembre!AI$12:AI$44,MATCH($B25,Novembre!$B$12:$B$44,0)),INDEX(Dicembre!AI$12:AI$44,MATCH($B25,Dicembre!$B$12:$B$44,0)),INDEX(Gennaio!AI$12:AI$44,MATCH($B25,Gennaio!$B$12:$B$44,0)),INDEX(Febbraio!AI$12:AI$44,MATCH($B25,Febbraio!$B$12:$B$44,0)),INDEX(Marzo!AI$12:AI$44,MATCH($B25,Marzo!$B$12:$B$44,0)),INDEX(Aprile!AI$12:AI$44,MATCH($B25,Aprile!$B$12:$B$44,0)),INDEX(Maggio!AI$12:AI$44,MATCH($B25,Maggio!$B$12:$B$44,0)),INDEX(Giugno!AI$12:AI$44,MATCH($B25,Giugno!$B$12:$B$44,0)),INDEX(Luglio!AI$12:AI$44,MATCH($B25,Luglio!$B$12:$B$44,0)))) -> 0 | E25: =IF(OR(ISBLANK($B25),ISBLANK($C25)),0,SUM(INDEX(Agosto!AJ$12:AJ$44,MATCH($B25,Agosto!$B$12:$B$44,0)),INDEX(Settembre!AJ$12:AJ$44,MATCH($B25,Settembre!$B$12:$B$44,0)),INDEX(Ottobre!AJ$12:AJ$44,MATCH($B25,Ottobre!$B$12:$B$44,0)),INDEX(Novembre!AJ$12:AJ$44,MATCH($B25,Novembre!$B$12:$B$44,0)),INDEX(Dicembre!AJ$12:AJ$44,MATCH($B25,Dicembre!$B$12:$B$44,0)),INDEX(Gennaio!AJ$12:AJ$44,MATCH($B25,Gennaio!$B$12:$B$44,0)),INDEX(Febbraio!AJ$12:AJ$44,MATCH($B25,Febbraio!$B$12:$B$44,0)),INDEX(Marzo!AJ$12:AJ$44,MATCH($B25,Marzo!$B$12:$B$44,0)),INDEX(Aprile!AJ$12:AJ$44,MATCH($B25,Aprile!$B$12:$B$44,0)),INDEX(Maggio!AJ$12:AJ$44,MATCH($B25,Maggio!$B$12:$B$44,0)),INDEX(Giugno!AJ$12:AJ$44,MATCH($B25,Giugno!$B$12:$B$44,0)),INDEX(Luglio!AJ$12:AJ$44,MATCH($B25,Luglio!$B$12:$B$44,0)))) -> 0 | F25: =IF(OR(ISBLANK($B25),ISBLANK($C25)),0,SUM(INDEX(Agosto!AK$12:AK$44,MATCH($B25,Agosto!$B$12:$B$44,0)),INDEX(Settembre!AK$12:AK$44,MATCH($B25,Settembre!$B$12:$B$44,0)),INDEX(Ottobre!AK$12:AK$44,MATCH($B25,Ottobre!$B$12:$B$44,0)),INDEX(Novembre!AK$12:AK$44,MATCH($B25,Novembre!$B$12:$B$44,0)),INDEX(Dicembre!AK$12:AK$44,MATCH($B25,Dicembre!$B$12:$B$44,0)),INDEX(Gennaio!AK$12:AK$44,MATCH($B25,Gennaio!$B$12:$B$44,0)),INDEX(Febbraio!AK$12:AK$44,MATCH($B25,Febbraio!$B$12:$B$44,0)),INDEX(Marzo!AK$12:AK$44,MATCH($B25,Marzo!$B$12:$B$44,0)),INDEX(Aprile!AK$12:AK$44,MATCH($B25,Aprile!$B$12:$B$44,0)),INDEX(Maggio!AK$12:AK$44,MATCH($B25,Maggio!$B$12:$B$44,0)),INDEX(Giugno!AK$12:AK$44,MATCH($B25,Giugno!$B$12:$B$44,0)),INDEX(Luglio!AK$12:AK$44,MATCH($B25,Luglio!$B$12:$B$44,0)))) -> 0 | G25: =IF(OR(ISBLANK($B25),ISBLANK($C25)),0,SUM(INDEX(Agosto!AL$12:AL$44,MATCH($B25,Agosto!$B$12:$B$44,0)),INDEX(Settembre!AL$12:AL$44,MATCH($B25,Settembre!$B$12:$B$44,0)),INDEX(Ottobre!AL$12:AL$44,MATCH($B25,Ottobre!$B$12:$B$44,0)),INDEX(Novembre!AL$12:AL$44,MATCH($B25,Novembre!$B$12:$B$44,0)),INDEX(Dicembre!AL$12:AL$44,MATCH($B25,Dicembre!$B$12:$B$44,0)),INDEX(Gennaio!AL$12:AL$44,MATCH($B25,Gennaio!$B$12:$B$44,0)),INDEX(Febbraio!AL$12:AL$44,MATCH($B25,Febbraio!$B$12:$B$44,0)),INDEX(Marzo!AL$12:AL$44,MATCH($B25,Marzo!$B$12:$B$44,0)),INDEX(Aprile!AL$12:AL$44,MATCH($B25,Aprile!$B$12:$B$44,0)),INDEX(Maggio!AL$12:AL$44,MATCH($B25,Maggio!$B$12:$B$44,0)),INDEX(Giugno!AL$12:AL$44,MATCH($B25,Giugno!$B$12:$B$44,0)),INDEX(Luglio!AL$12:AL$44,MATCH($B25,Luglio!$B$12:$B$44,0)))) -> 0 | H25: =IF(OR(ISBLANK($B25),ISBLANK($C25)),0,SUM(INDEX(Agosto!AM$12:AM$44,MATCH($B25,Agosto!$B$12:$B$44,0)),INDEX(Settembre!AM$12:AM$44,MATCH($B25,Settembre!$B$12:$B$44,0)),INDEX(Ottobre!AM$12:AM$44,MATCH($B25,Ottobre!$B$12:$B$44,0)),INDEX(Novembre!AM$12:AM$44,MATCH($B25,Novembre!$B$12:$B$44,0)),INDEX(Dicembre!AM$12:AM$44,MATCH($B25,Dicembre!$B$12:$B$44,0)),INDEX(Gennaio!AM$12:AM$44,MATCH($B25,Gennaio!$B$12:$B$44,0)),INDEX(Febbraio!AM$12:AM$44,MATCH($B25,Febbraio!$B$12:$B$44,0)),INDEX(Marzo!AM$12:AM$44,MATCH($B25,Marzo!$B$12:$B$44,0)),INDEX(Aprile!AM$12:AM$44,MATCH($B25,Aprile!$B$12:$B$44,0)),INDEX(Maggio!AM$12:AM$44,MATCH($B25,Maggio!$B$12:$B$44,0)),INDEX(Giugno!AM$12:AM$44,MATCH($B25,Giugno!$B$12:$B$44,0)),INDEX(Luglio!AM$12:AM$44,MATCH($B25,Luglio!$B$12:$B$44,0)))) -> 0 | I25: =IF(Q10=0,0,D25/Q10) -> 0 | J25: =IF(Q10=0,0,E25/Q10) -> 0 | K25: =IF(Q10=0,0,F25/Q10) -> 0 | L25: =IF(Q10=0,0,G25/Q10) -> 0 | M25: =IF(Q10=0,0,H25/Q10) -> 0
